Workbook

Sheet OPENING STOCK
A1: Mahavishnu | C1: OPENING STOCK
C2: 750 ML | E2: 375 ML | G2: 180 ML | I2: 90 ML | K2: 60 ML
A3: SL. | B3: PRODUCT NAME | C3: CASES*12 | D3: BTLS | E3: CASES*24 | F3: BTLS | G3: CASES*48 | H3: BTLS | I3: CASES*96 | J3: BTLS | K3: BOX*25 | L3: BTLS
A4: 1 | B4: ='SALES & RATE'!B4 -> M H BRANDY | C4: 0 | D4: 10 | E4: 0 | F4: 11 | G4: 8 | H4: 41 | I4: 6 | J4: 70 | K4: 0 | L4: 0
A5: 2 | B5: ='SALES & RATE'!B5 -> MC BRANDY | C5: 0 | D5: 14 | E5: 1 | F5: 11 | G5: 10 | H5: 97 | I5: 6 | J5: 72 | K5: 0 | L5: 0
A6: 3 | B6: ='SALES & RATE'!B6 -> O.C.BRANDY | C6: 0 | D6: 0 | E6: 0 | F6: 0 | G6: 2 | H6: 89 | I6: 5 | J6: 42 | K6: 0 | L6: 0
A7: 4 | B7: ='SALES & RATE'!B7 -> AMRUT SILVER CUP | C7: 0 | D7: 0 | E7: 0 | F7: 0 | G7: 8 | H7: 46 | I7: 1 | J7: 2 | K7: 0 | L7: 0
A8: 5 | B8: ='SALES & RATE'!B8 -> HONEY BEE BRANDY | C8: 0 | D8: 0 | E8: 0 | F8: 0 | G8: 0 | H8: 26 | I8: 0 | J8: 54 | K8: 0 | L8: 0
A9: 6 | B9: ='SALES & RATE'!B9 -> O A BRANDY | C9: 0 | D9: 3 | E9: 0 | F9: 0 | G9: 1 | H9: 92 | I9: 3 | J9: 61 | K9: 0 | L9: 0
A10: 7 | B10: ='SALES & RATE'!B10 -> BEJOIS BRANDY | C10: 0 | D10: 6 | E10: 0 | F10: 0 | G10: 6 | H10: 59 | I10: 7 | J10: 19 | K10: 0 | L10: 0
A11: 8 | B11: ='SALES & RATE'!B11 -> MORPHIS BRANDY | C11: 0 | D11: 0 | E11: 0 | F11: 0 | G11: 0 | H11: 35 | I11: 0 | J11: 0 | K11: 0 | L11: 33
A12: 9 | B12: ='SALES & RATE'!B12 -> M C WHISKY | C12: 0 | D12: 10 | E12: 0 | F12: 15 | G12: 1 | H12: 52 | I12: 1 | J12: 95 | K12: 0 | L12: 0
A13: 10 | B13: ='SALES & RATE'!B13 -> BAGPIPER (W) | C13: 0 | D13: 11 | E13: 0 | F13: 9 | G13: 16 | H13: 51 | I13: 4 | J13: 49 | K13: 0 | L13: 0
A14: 11 | B14: ='SALES & RATE'!B14 -> SIGNATURE (W) | C14: 0 | D14: 0 | E14: 0 | F14: 0 | G14: 0 | H14: 31 | I14: 0 | J14: 0 | K14: 0 | L14: 0
A15: 12 | B15: ='SALES & RATE'!B15 -> O T WHISKY | C15: 0 | D15: 0 | E15: 0 | F15: 0 | G15: 2 | H15: 23 | I15: 0 | J15: 99 | K15: 0 | L15: 0
... A50: 47 | B50: ='SALES & RATE'!B50 -> 0 | C50: 0 | D50: 0 | E50: 0 | F50: 0 | G50: 0 | H50: 0 | I50: 0 | J50: 0 | K50: 0 | L50: 0
A51: Mahavishnu PAGE 2 | C51: OPENING STOCK PAGE 2
C52: 750 ML | E52: 375 ML | G52: 180 ML | I52: 90 ML | K52: 60 ML
A53: SL. | B53: PRODUCT NAME | C53: CASES*12 | D53: BTLS | E53: CASES*24 | F53: BTLS | G53: CASES*48 | H53: BTLS | I53: CASES*96 | J53: BTLS | K53: BOX*25 | L53: BTLS
A54: 1 | B54: ='SALES & RATE'!B54 -> CARNIVAL GIN | C54: 0 | D54: 0 | E54: 0 | F54: 0 | G54: 1 | H54: 16 | I54: 0 | J54: 82 | K54: 0 | L54: 0
A55: 2 | B55: ='SALES & RATE'!B55 -> SMIRNOFF VODKA | C55: 0 | D55: 4 | E55: 0 | F55: 0 | G55: 0 | H55: 59 | I55: 0 | J55: 0 | K55: 0 | L55: 20
A56: 3 | B56: ='SALES & RATE'!B56 -> MUSCOVY LEMON | C56: 0 | D56: 0 | E56: 0 | F56: 0 | G56: 0 | H56: 48 | I56: 0 | J56: 0 | K56: 0 | L56: 0
A57: 4 | B57: ='SALES & RATE'!B57 -> MUSCOVY VODKA | C57: 0 | D57: 0 | E57: 0 | F57: 0 | G57: 2 | H57: 89 | I57: 0 | J57: 95 | K57: 0 | L57: 0
A58: 5 | B58: ='SALES & RATE'!B58 -> ROMANOV VODKA | C58: 0 | D58: 0 | E58: 0 | F58: 0 | G58: 1 | H58: 56 | I58: 0 | J58: 96 | K58: 0 | L58: 0
A59: 6 | B59: ='SALES & RATE'!B59 -> GONAS WINE | C59: 0 | D59: 0 | E59: 0 | F59: 0 | G59: 0 | H59: 39 | I59: 0 | J59: 0 | K59: 0 | L59: 0
A60: 7 | B60: ='SALES & RATE'!B60 -> MAGIC PORT WINE | C60: 0 | D60: 20 | E60: 0 | F60: 24 | G60: 0 | H60: 12 | I60: 0 | J60: 0 | K60: 0 | L60: 0
A61: 8 | B61: ='SALES & RATE'!B61 -> SIDDUS WINE | C61: 0 | D61: 1 | E61: 0 | F61: 1 | G61: 0 | H61: 34 | I61: 0 | J61: 0 | K61: 0 | L61: 0
A62: 9 | B62: ='SALES & RATE'!B62 -> VEGA WINE | C62: 0 | D62: 0 | E62: 0 | F62: 13 | G62: 0 | H62: 0 | I62: 0 | J62: 0 | K62: 0 | L62: 0
A63: 10 | B63: ='SALES & RATE'!B63 -> 0 | C63: 0 | D63: 0 | E63: 0 | F63: 0 | G63: 0 | H63: 0 | I63: 0 | J63: 0 | K63: 0 | L63: 0
A64: 11 | B64: ='SALES & RATE'!B64 -> MAGIC MOMENTS | C64: 0 | D64: 2 | E64: 0 | F64: 0 | G64: 0 | H64: 0 | I64: 0 | J64: 0 | K64: 0 | L64: 6
A65: 12 | B65: ='SALES & RATE'!B65 -> BRO CODE | C65: 0 | D65: 0 | E65: 0 | F65: 26 | G65: 0 | H65: 0 | I65: 0 | J65: 0 | K65: 0 | L65: 0
... A71: 18 | B71: ='SALES & RATE'!B71 -> 0 | C71: 0 | D71: 0 | E71: 0 | F71: 0 | G71: 0 | H71: 0 | I71: 0 | J71: 0 | K71: 0 | L71: 0
A72: BEERS | C72: OPENING STOCK
C73: 650 ML | E73: 500 ML TIN(CAN) | G73: 330 ML (PINT) | I73: 330 ML TIN(CAN) | M73: PREVIOUS CLOSINGS
A74: SL. | B74: PRODUCT NAME | C74: CASES*12 | D74: BTLS | E74: CASES*24 | F74: BTLS | G74: CASES*24 | H74: BTLS | I74: CASES*24 | J74: BTLS | M74: PREV. CREDIT BILLS
A75: 1 | B75: ='SALES & RATE'!B75 -> K.F PREMIUM | C75: 1 | D75: 15 | E75: 0 | F75: 0 | G75: 0 | H75: 0 | I75: 0 | J75: 0 | M75: 93990
A76: 2 | B76: ='SALES & RATE'!B76 -> K.F STRONG | C76: 47 | D76: 32 | E76: 0 | F76: 1 | G76: 0 | H76: 0 | I76: 0 | J76: 0 | M76: PREV. GALLA CASH
A77: 3 | B77: ='SALES & RATE'!B77 -> U.B EXPORT | C77: 1 | D77: 28 | E77: 0 | F77: 0 | G77: 0 | H77: 0 | I77: 0 | J77: 0 | M77: 24950
A78: 4 | B78: ='SALES & RATE'!B78 -> KNOCK OUT | C78: 0 | D78: 0 | E78: 0 | F78: 0 | G78: 1 | H78: 10 | I78: 0 | J78: 0 | M78: PREV. CIGRETE
A79: 5 | B79: ='SALES & RATE'!B79 -> K.F STROM | C79: 0 | D79: 0 | E79: 0 | F79: 0 | G79: 0 | H79: 0 | I79: 0 | J79: 0 | M79: 35135
...

Sheet RECIEPTS
A1: Mahavishnu | C1: RECIEPTS INVOICE
C2: 750 ML | D2: 375 ML | E2: 180 ML | F2: 90 ML | G2: 60 ML
A3: SL. | B3: PRODUCT NAME | C3: CASES*12 | D3: CASES*24 | E3: CASES*48 | F3: CASES*96 | G3: BOX*25
A4: 1 | B4: ='SALES & RATE'!B4 -> M H BRANDY | C4: 0 | D4: 1 | E4: 2 | F4: 1 | G4: 0
A5: 2 | B5: ='SALES & RATE'!B5 -> MC BRANDY | C5: 0 | D5: 0 | E5: 2 | F5: 1 | G5: 0
A6: 3 | B6: ='SALES & RATE'!B6 -> O.C.BRANDY | C6: 0 | D6: 0 | E6: 4 | F6: 0 | G6: 0
A7: 4 | B7: ='SALES & RATE'!B7 -> AMRUT SILVER CUP | C7: 0 | D7: 0 | E7: 0 | F7: 5 | G7: 0
A8: 5 | B8: ='SALES & RATE'!B8 -> HONEY BEE BRANDY | C8: 0 | D8: 0 | E8: 0 | F8: 0 | G8: 0
A9: 6 | B9: ='SALES & RATE'!B9 -> O A BRANDY | C9: 0 | D9: 0 | E9: 2 | F9: 1 | G9: 0
A10: 7 | B10: ='SALES & RATE'!B10 -> BEJOIS BRANDY | C10: 0 | D10: 0 | E10: 2 | F10: 0 | G10: 0
A11: 8 | B11: ='SALES & RATE'!B11 -> MORPHIS BRANDY | C11: 0 | D11: 0 | E11: 0 | F11: 0 | G11: 0
A12: 9 | B12: ='SALES & RATE'!B12 -> M C WHISKY | C12: 0 | D12: 0 | E12: 1 | F12: 0 | G12: 0
A13: 10 | B13: ='SALES & RATE'!B13 -> BAGPIPER (W) | C13: 0 | D13: 0 | E13: 0 | F13: 2 | G13: 0
A14: 11 | B14: ='SALES & RATE'!B14 -> SIGNATURE (W) | C14: 0 | D14: 0 | E14: 0 | F14: 0 | G14: 0
A15: 12 | B15: ='SALES & RATE'!B15 -> O T WHISKY | C15: 0 | D15: 0 | E15: 0 | F15: 0 | G15: 0
... A50: 47 | B50: ='SALES & RATE'!B50 -> 0 | C50: 0 | D50: 0 | E50: 0 | F50: 0 | G50: 0
A51: Mahavishnu PAGE 2 | C51: RECIEPTS INVOICE
C52: 750 ML | D52: 375 ML | E52: 180 ML | F52: 90 ML | G52: 60 ML
A53: SL. | B53: PRODUCT NAME | C53: CASES*12 | D53: CASES*24 | E53: CASES*48 | F53: CASES*96 | G53: BOX*25
A54: 1 | B54: ='SALES & RATE'!B54 -> CARNIVAL GIN | C54: 0 | D54: 0 | E54: 0 | F54: 0 | G54: 0
A55: 2 | B55: ='SALES & RATE'!B55 -> SMIRNOFF VODKA | C55: 0 | D55: 0 | E55: 0 | F55: 0 | G55: 0
A56: 3 | B56: ='SALES & RATE'!B56 -> MUSCOVY LEMON | C56: 0 | D56: 0 | E56: 0 | F56: 0 | G56: 0
A57: 4 | B57: ='SALES & RATE'!B57 -> MUSCOVY VODKA | C57: 0 | D57: 0 | E57: 2 | F57: 1 | G57: 0
A58: 5 | B58: ='SALES & RATE'!B58 -> ROMANOV VODKA | C58: 0 | D58: 0 | E58: 0 | F58: 1 | G58: 0
A59: 6 | B59: ='SALES & RATE'!B59 -> GONAS WINE | C59: 0 | D59: 0 | E59: 0 | F59: 0 | G59: 0
A60: 7 | B60: ='SALES & RATE'!B60 -> MAGIC PORT WINE | C60: 0 | D60: 0 | E60: 0 | F60: 0 | G60: 0
A61: 8 | B61: ='SALES & RATE'!B61 -> SIDDUS WINE | C61: 0 | D61: 0 | E61: 0 | F61: 0 | G61: 0
A62: 9 | B62: ='SALES & RATE'!B62 -> VEGA WINE | C62: 0 | D62: 0 | E62: 0 | F62: 0 | G62: 0
A63: 10 | B63: ='SALES & RATE'!B63 -> 0 | C63: 0 | D63: 0 | E63: 0 | F63: 0 | G63: 0
A64: 11 | B64: ='SALES & RATE'!B64 -> MAGIC MOMENTS | C64: 0 | D64: 0 | E64: 1 | F64: 0 | G64: 1
A65: 12 | B65: ='SALES & RATE'!B65 -> BRO CODE | C65: 0 | D65: 0 | E65: 0 | F65: 0 | G65: 0
... A71: 18 | B71: ='SALES & RATE'!B71 -> 0 | C71: 0 | D71: 0 | E71: 0 | F71: 0 | G71: 0
A72: BEERS | C72: RECIEPTS INVOICE
C73: 650 ML | D73: 500 CAN | E73: 330 PINT | F73: 330 CAN
A74: SL. | B74: PRODUCT NAME | C74: CASES*12 | D74: CASES*24 | E74: CASES*24 | F74: CASES*24
A75: 1 | B75: ='SALES & RATE'!B75 -> K.F PREMIUM | C75: 0 | D75: 0 | E75: 0 | F75: 0
A76: 2 | B76: ='SALES & RATE'!B76 -> K.F STRONG | C76: 50 | D76: 2 | E76: 3 | F76: 1
A77: 3 | B77: ='SALES & RATE'!B77 -> U.B EXPORT | C77: 0 | D77: 0 | E77: 0 | F77: 0
A78: 4 | B78: ='SALES & RATE'!B78 -> KNOCK OUT | C78: 5 | D78: 0 | E78: 0 | F78: 0
A79: 5 | B79: ='SALES & RATE'!B79 -> K.F STROM | C79: 0 | D79: 0 | E79: 0 | F79: 0
...

Sheet TOTAL STOCK
A1: Mahavishnu | C1: TOTAL STOCK
C2: 750 ML | E2: 375 ML | G2: 180 ML | I2: 90 ML | K2: 60 ML
A3: SL. | B3: PRODUCT NAME | C3: CASES*12 | D3: BTLS | E3: CASES*24 | F3: BTLS | G3: CASES*48 | H3: BTLS | I3: CASES*96 | J3: BTLS | K3: BOX*25 | L3: BTLS
A4: 1 | B4: ='SALES & RATE'!B4 -> M H BRANDY | C4: ='OPENING STOCK'!C4+RECIEPTS!C4 -> 0 | D4: ='OPENING STOCK'!D4 -> 10 | E4: ='OPENING STOCK'!E4+RECIEPTS!D4 -> 1 | F4: ='OPENING STOCK'!F4 -> 11 | G4: ='OPENING STOCK'!G4+RECIEPTS!E4 -> 10 | H4: ='OPENING STOCK'!H4 -> 41 | I4: ='OPENING STOCK'!I4+RECIEPTS!F4 -> 7 | J4: ='OPENING STOCK'!J4 -> 70 | K4: ='OPENING STOCK'!K4+RECIEPTS!G4 -> 0 | L4: ='OPENING STOCK'!L4 -> 0
A5: 2 | B5: ='SALES & RATE'!B5 -> MC BRANDY | C5: ='OPENING STOCK'!C5+RECIEPTS!C5 -> 0 | D5: ='OPENING STOCK'!D5 -> 14 | E5: ='OPENING STOCK'!E5+RECIEPTS!D5 -> 1 | F5: ='OPENING STOCK'!F5 -> 11 | G5: ='OPENING STOCK'!G5+RECIEPTS!E5 -> 12 | H5: ='OPENING STOCK'!H5 -> 97 | I5: ='OPENING STOCK'!I5+RECIEPTS!F5 -> 7 | J5: ='OPENING STOCK'!J5 -> 72 | K5: ='OPENING STOCK'!K5+RECIEPTS!G5 -> 0 | L5: ='OPENING STOCK'!L5 -> 0
A6: 3 | B6: ='SALES & RATE'!B6 -> O.C.BRANDY | C6: ='OPENING STOCK'!C6+RECIEPTS!C6 -> 0 | D6: ='OPENING STOCK'!D6 -> 0 | E6: ='OPENING STOCK'!E6+RECIEPTS!D6 -> 0 | F6: ='OPENING STOCK'!F6 -> 0 | G6: ='OPENING STOCK'!G6+RECIEPTS!E6 -> 6 | H6: ='OPENING STOCK'!H6 -> 89 | I6: ='OPENING STOCK'!I6+RECIEPTS!F6 -> 5 | J6: ='OPENING STOCK'!J6 -> 42 | K6: ='OPENING STOCK'!K6+RECIEPTS!G6 -> 0 | L6: ='OPENING STOCK'!L6 -> 0
A7: 4 | B7: ='SALES & RATE'!B7 -> AMRUT SILVER CUP | C7: ='OPENING STOCK'!C7+RECIEPTS!C7 -> 0 | D7: ='OPENING STOCK'!D7 -> 0 | E7: ='OPENING STOCK'!E7+RECIEPTS!D7 -> 0 | F7: ='OPENING STOCK'!F7 -> 0 | G7: ='OPENING STOCK'!G7+RECIEPTS!E7 -> 8 | H7: ='OPENING STOCK'!H7 -> 46 | I7: ='OPENING STOCK'!I7+RECIEPTS!F7 -> 6 | J7: ='OPENING STOCK'!J7 -> 2 | K7: ='OPENING STOCK'!K7+RECIEPTS!G7 -> 0 | L7: ='OPENING STOCK'!L7 -> 0
A8: 5 | B8: ='SALES & RATE'!B8 -> HONEY BEE BRANDY | C8: ='OPENING STOCK'!C8+RECIEPTS!C8 -> 0 | D8: ='OPENING STOCK'!D8 -> 0 | E8: ='OPENING STOCK'!E8+RECIEPTS!D8 -> 0 | F8: ='OPENING STOCK'!F8 -> 0 | G8: ='OPENING STOCK'!G8+RECIEPTS!E8 -> 0 | H8: ='OPENING STOCK'!H8 -> 26 | I8: ='OPENING STOCK'!I8+RECIEPTS!F8 -> 0 | J8: ='OPENING STOCK'!J8 -> 54 | K8: ='OPENING STOCK'!K8+RECIEPTS!G8 -> 0 | L8: ='OPENING STOCK'!L8 -> 0
A9: 6 | B9: ='SALES & RATE'!B9 -> O A BRANDY | C9: ='OPENING STOCK'!C9+RECIEPTS!C9 -> 0 | D9: ='OPENING STOCK'!D9 -> 3 | E9: ='OPENING STOCK'!E9+RECIEPTS!D9 -> 0 | F9: ='OPENING STOCK'!F9 -> 0 | G9: ='OPENING STOCK'!G9+RECIEPTS!E9 -> 3 | H9: ='OPENING STOCK'!H9 -> 92 | I9: ='OPENING STOCK'!I9+RECIEPTS!F9 -> 4 | J9: ='OPENING STOCK'!J9 -> 61 | K9: ='OPENING STOCK'!K9+RECIEPTS!G9 -> 0 | L9: ='OPENING STOCK'!L9 -> 0
A10: 7 | B10: ='SALES & RATE'!B10 -> BEJOIS BRANDY | C10: ='OPENING STOCK'!C10+RECIEPTS!C10 -> 0 | D10: ='OPENING STOCK'!D10 -> 6 | E10: ='OPENING STOCK'!E10+RECIEPTS!D10 -> 0 | F10: ='OPENING STOCK'!F10 -> 0 | G10: ='OPENING STOCK'!G10+RECIEPTS!E10 -> 8 | H10: ='OPENING STOCK'!H10 -> 59 | I10: ='OPENING STOCK'!I10+RECIEPTS!F10 -> 7 | J10: ='OPENING STOCK'!J10 -> 19 | K10: ='OPENING STOCK'!K10+RECIEPTS!G10 -> 0 | L10: ='OPENING STOCK'!L10 -> 0
A11: 8 | B11: ='SALES & RATE'!B11 -> MORPHIS BRANDY | C11: ='OPENING STOCK'!C11+RECIEPTS!C11 -> 0 | D11: ='OPENING STOCK'!D11 -> 0 | E11: ='OPENING STOCK'!E11+RECIEPTS!D11 -> 0 | F11: ='OPENING STOCK'!F11 -> 0 | G11: ='OPENING STOCK'!G11+RECIEPTS!E11 -> 0 | H11: ='OPENING STOCK'!H11 -> 35 | I11: ='OPENING STOCK'!I11+RECIEPTS!F11 -> 0 | J11: ='OPENING STOCK'!J11 -> 0 | K11: ='OPENING STOCK'!K11+RECIEPTS!G11 -> 0 | L11: ='OPENING STOCK'!L11 -> 33
A12: 9 | B12: ='SALES & RATE'!B12 -> M C WHISKY | C12: ='OPENING STOCK'!C12+RECIEPTS!C12 -> 0 | D12: ='OPENING STOCK'!D12 -> 10 | E12: ='OPENING STOCK'!E12+RECIEPTS!D12 -> 0 | F12: ='OPENING STOCK'!F12 -> 15 | G12: ='OPENING STOCK'!G12+RECIEPTS!E12 -> 2 | H12: ='OPENING STOCK'!H12 -> 52 | I12: ='OPENING STOCK'!I12+RECIEPTS!F12 -> 1 | J12: ='OPENING STOCK'!J12 -> 95 | K12: ='OPENING STOCK'!K12+RECIEPTS!G12 -> 0 | L12: ='OPENING STOCK'!L12 -> 0
A13: 10 | B13: ='SALES & RATE'!B13 -> BAGPIPER (W) | C13: ='OPENING STOCK'!C13+RECIEPTS!C13 -> 0 | D13: ='OPENING STOCK'!D13 -> 11 | E13: ='OPENING STOCK'!E13+RECIEPTS!D13 -> 0 | F13: ='OPENING STOCK'!F13 -> 9 | G13: ='OPENING STOCK'!G13+RECIEPTS!E13 -> 16 | H13: ='OPENING STOCK'!H13 -> 51 | I13: ='OPENING STOCK'!I13+RECIEPTS!F13 -> 6 | J13: ='OPENING STOCK'!J13 -> 49 | K13: ='OPENING STOCK'!K13+RECIEPTS!G13 -> 0 | L13: ='OPENING STOCK'!L13 -> 0
A14: 11 | B14: ='SALES & RATE'!B14 -> SIGNATURE (W) | C14: ='OPENING STOCK'!C14+RECIEPTS!C14 -> 0 | D14: ='OPENING STOCK'!D14 -> 0 | E14: ='OPENING STOCK'!E14+RECIEPTS!D14 -> 0 | F14: ='OPENING STOCK'!F14 -> 0 | G14: ='OPENING STOCK'!G14+RECIEPTS!E14 -> 0 | H14: ='OPENING STOCK'!H14 -> 31 | I14: ='OPENING STOCK'!I14+RECIEPTS!F14 -> 0 | J14: ='OPENING STOCK'!J14 -> 0 | K14: ='OPENING STOCK'!K14+RECIEPTS!G14 -> 0 | L14: ='OPENING STOCK'!L14 -> 0
A15: 12 | B15: ='SALES & RATE'!B15 -> O T WHISKY | C15: ='OPENING STOCK'!C15+RECIEPTS!C15 -> 0 | D15: ='OPENING STOCK'!D15 -> 0 | E15: ='OPENING STOCK'!E15+RECIEPTS!D15 -> 0 | F15: ='OPENING STOCK'!F15 -> 0 | G15: ='OPENING STOCK'!G15+RECIEPTS!E15 -> 2 | H15: ='OPENING STOCK'!H15 -> 23 | I15: ='OPENING STOCK'!I15+RECIEPTS!F15 -> 0 | J15: ='OPENING STOCK'!J15 -> 99 | K15: ='OPENING STOCK'!K15+RECIEPTS!G15 -> 0 | L15: ='OPENING STOCK'!L15 -> 0
... A50: 47 | B50: ='SALES & RATE'!B50 -> 0 | C50: ='OPENING STOCK'!C50+RECIEPTS!C50 -> 0 | D50: ='OPENING STOCK'!D50 -> 0 | E50: ='OPENING STOCK'!E50+RECIEPTS!D50 -> 0 | F50: ='OPENING STOCK'!F50 -> 0 | G50: ='OPENING STOCK'!G50+RECIEPTS!E50 -> 0 | H50: ='OPENING STOCK'!H50 -> 0 | I50: ='OPENING STOCK'!I50+RECIEPTS!F50 -> 0 | J50: ='OPENING STOCK'!J50 -> 0 | K50: ='OPENING STOCK'!K50+RECIEPTS!G50 -> 0 | L50: ='OPENING STOCK'!L50 -> 0
A51: Mahavishnu PAGE 2 | C51: TOTAL STOCK PAGE 2
C52: 750 ML | E52: 375 ML | G52: 180 ML | I52: 90 ML | K52: 60 ML
A53: SL. | B53: PRODUCT NAME | C53: CASES*12 | D53: BTLS | E53: CASES*24 | F53: BTLS | G53: CASES*48 | H53: BTLS | I53: CASES*96 | J53: BTLS | K53: BOX*25 | L53: BTLS
A54: 1 | B54: ='SALES & RATE'!B54 -> CARNIVAL GIN | C54: ='OPENING STOCK'!C54+RECIEPTS!C54 -> 0 | D54: ='OPENING STOCK'!D54 -> 0 | E54: ='OPENING STOCK'!E54+RECIEPTS!D54 -> 0 | F54: ='OPENING STOCK'!F54 -> 0 | G54: ='OPENING STOCK'!G54+RECIEPTS!E54 -> 1 | H54: ='OPENING STOCK'!H54 -> 16 | I54: ='OPENING STOCK'!I54+RECIEPTS!F54 -> 0 | J54: ='OPENING STOCK'!J54 -> 82 | K54: ='OPENING STOCK'!K54+RECIEPTS!G54 -> 0 | L54: ='OPENING STOCK'!L54 -> 0
A55: 2 | B55: ='SALES & RATE'!B55 -> SMIRNOFF VODKA | C55: ='OPENING STOCK'!C55+RECIEPTS!C55 -> 0 | D55: ='OPENING STOCK'!D55 -> 4 | E55: ='OPENING STOCK'!E55+RECIEPTS!D55 -> 0 | F55: ='OPENING STOCK'!F55 -> 0 | G55: ='OPENING STOCK'!G55+RECIEPTS!E55 -> 0 | H55: ='OPENING STOCK'!H55 -> 59 | I55: ='OPENING STOCK'!I55+RECIEPTS!F55 -> 0 | J55: ='OPENING STOCK'!J55 -> 0 | K55: ='OPENING STOCK'!K55+RECIEPTS!G55 -> 0 | L55: ='OPENING STOCK'!L55 -> 20
A56: 3 | B56: ='SALES & RATE'!B56 -> MUSCOVY LEMON | C56: ='OPENING STOCK'!C56+RECIEPTS!C56 -> 0 | D56: ='OPENING STOCK'!D56 -> 0 | E56: ='OPENING STOCK'!E56+RECIEPTS!D56 -> 0 | F56: ='OPENING STOCK'!F56 -> 0 | G56: ='OPENING STOCK'!G56+RECIEPTS!E56 -> 0 | H56: ='OPENING STOCK'!H56 -> 48 | I56: ='OPENING STOCK'!I56+RECIEPTS!F56 -> 0 | J56: ='OPENING STOCK'!J56 -> 0 | K56: ='OPENING STOCK'!K56+RECIEPTS!G56 -> 0 | L56: ='OPENING STOCK'!L56 -> 0
A57: 4 | B57: ='SALES & RATE'!B57 -> MUSCOVY VODKA | C57: ='OPENING STOCK'!C57+RECIEPTS!C57 -> 0 | D57: ='OPENING STOCK'!D57 -> 0 | E57: ='OPENING STOCK'!E57+RECIEPTS!D57 -> 0 | F57: ='OPENING STOCK'!F57 -> 0 | G57: ='OPENING STOCK'!G57+RECIEPTS!E57 -> 4 | H57: ='OPENING STOCK'!H57 -> 89 | I57: ='OPENING STOCK'!I57+RECIEPTS!F57 -> 1 | J57: ='OPENING STOCK'!J57 -> 95 | K57: ='OPENING STOCK'!K57+RECIEPTS!G57 -> 0 | L57: ='OPENING STOCK'!L57 -> 0
A58: 5 | B58: ='SALES & RATE'!B58 -> ROMANOV VODKA | C58: ='OPENING STOCK'!C58+RECIEPTS!C58 -> 0 | D58: ='OPENING STOCK'!D58 -> 0 | E58: ='OPENING STOCK'!E58+RECIEPTS!D58 -> 0 | F58: ='OPENING STOCK'!F58 -> 0 | G58: ='OPENING STOCK'!G58+RECIEPTS!E58 -> 1 | H58: ='OPENING STOCK'!H58 -> 56 | I58: ='OPENING STOCK'!I58+RECIEPTS!F58 -> 1 | J58: ='OPENING STOCK'!J58 -> 96 | K58: ='OPENING STOCK'!K58+RECIEPTS!G58 -> 0 | L58: ='OPENING STOCK'!L58 -> 0
A59: 6 | B59: ='SALES & RATE'!B59 -> GONAS WINE | C59: ='OPENING STOCK'!C59+RECIEPTS!C59 -> 0 | D59: ='OPENING STOCK'!D59 -> 0 | E59: ='OPENING STOCK'!E59+RECIEPTS!D59 -> 0 | F59: ='OPENING STOCK'!F59 -> 0 | G59: ='OPENING STOCK'!G59+RECIEPTS!E59 -> 0 | H59: ='OPENING STOCK'!H59 -> 39 | I59: ='OPENING STOCK'!I59+RECIEPTS!F59 -> 0 | J59: ='OPENING STOCK'!J59 -> 0 | K59: ='OPENING STOCK'!K59+RECIEPTS!G59 -> 0 | L59: ='OPENING STOCK'!L59 -> 0
A60: 7 | B60: ='SALES & RATE'!B60 -> MAGIC PORT WINE | C60: ='OPENING STOCK'!C60+RECIEPTS!C60 -> 0 | D60: ='OPENING STOCK'!D60 -> 20 | E60: ='OPENING STOCK'!E60+RECIEPTS!D60 -> 0 | F60: ='OPENING STOCK'!F60 -> 24 | G60: ='OPENING STOCK'!G60+RECIEPTS!E60 -> 0 | H60: ='OPENING STOCK'!H60 -> 12 | I60: ='OPENING STOCK'!I60+RECIEPTS!F60 -> 0 | J60: ='OPENING STOCK'!J60 -> 0 | K60: ='OPENING STOCK'!K60+RECIEPTS!G60 -> 0 | L60: ='OPENING STOCK'!L60 -> 0
A61: 8 | B61: ='SALES & RATE'!B61 -> SIDDUS WINE | C61: ='OPENING STOCK'!C61+RECIEPTS!C61 -> 0 | D61: ='OPENING STOCK'!D61 -> 1 | E61: ='OPENING STOCK'!E61+RECIEPTS!D61 -> 0 | F61: ='OPENING STOCK'!F61 -> 1 | G61: ='OPENING STOCK'!G61+RECIEPTS!E61 -> 0 | H61: ='OPENING STOCK'!H61 -> 34 | I61: ='OPENING STOCK'!I61+RECIEPTS!F61 -> 0 | J61: ='OPENING STOCK'!J61 -> 0 | K61: ='OPENING STOCK'!K61+RECIEPTS!G61 -> 0 | L61: ='OPENING STOCK'!L61 -> 0
A62: 9 | B62: ='SALES & RATE'!B62 -> VEGA WINE | C62: ='OPENING STOCK'!C62+RECIEPTS!C62 -> 0 | D62: ='OPENING STOCK'!D62 -> 0 | E62: ='OPENING STOCK'!E62+RECIEPTS!D62 -> 0 | F62: ='OPENING STOCK'!F62 -> 13 | G62: ='OPENING STOCK'!G62+RECIEPTS!E62 -> 0 | H62: ='OPENING STOCK'!H62 -> 0 | I62: ='OPENING STOCK'!I62+RECIEPTS!F62 -> 0 | J62: ='OPENING STOCK'!J62 -> 0 | K62: ='OPENING STOCK'!K62+RECIEPTS!G62 -> 0 | L62: ='OPENING STOCK'!L62 -> 0
A63: 10 | B63: ='SALES & RATE'!B63 -> 0 | C63: ='OPENING STOCK'!C63+RECIEPTS!C63 -> 0 | D63: ='OPENING STOCK'!D63 -> 0 | E63: ='OPENING STOCK'!E63+RECIEPTS!D63 -> 0 | F63: ='OPENING STOCK'!F63 -> 0 | G63: ='OPENING STOCK'!G63+RECIEPTS!E63 -> 0 | H63: ='OPENING STOCK'!H63 -> 0 | I63: ='OPENING STOCK'!I63+RECIEPTS!F63 -> 0 | J63: ='OPENING STOCK'!J63 -> 0 | K63: ='OPENING STOCK'!K63+RECIEPTS!G63 -> 0 | L63: ='OPENING STOCK'!L63 -> 0
A64: 11 | B64: ='SALES & RATE'!B64 -> MAGIC MOMENTS | C64: ='OPENING STOCK'!C64+RECIEPTS!C64 -> 0 | D64: ='OPENING STOCK'!D64 -> 2 | E64: ='OPENING STOCK'!E64+RECIEPTS!D64 -> 0 | F64: ='OPENING STOCK'!F64 -> 0 | G64: ='OPENING STOCK'!G64+RECIEPTS!E64 -> 1 | H64: ='OPENING STOCK'!H64 -> 0 | I64: ='OPENING STOCK'!I64+RECIEPTS!F64 -> 0 | J64: ='OPENING STOCK'!J64 -> 0 | K64: ='OPENING STOCK'!K64+RECIEPTS!G64 -> 1 | L64: ='OPENING STOCK'!L64 -> 6
A65: 12 | B65: ='SALES & RATE'!B65 -> BRO CODE | C65: ='OPENING STOCK'!C65+RECIEPTS!C65 -> 0 | D65: ='OPENING STOCK'!D65 -> 0 | E65: ='OPENING STOCK'!E65+RECIEPTS!D65 -> 0 | F65: ='OPENING STOCK'!F65 -> 26 | G65: ='OPENING STOCK'!G65+RECIEPTS!E65 -> 0 | H65: ='OPENING STOCK'!H65 -> 0 | I65: ='OPENING STOCK'!I65+RECIEPTS!F65 -> 0 | J65: ='OPENING STOCK'!J65 -> 0 | K65: ='OPENING STOCK'!K65+RECIEPTS!G65 -> 0 | L65: ='OPENING STOCK'!L65 -> 0
... A71: 18 | B71: ='SALES & RATE'!B71 -> 0 | C71: ='OPENING STOCK'!C71+RECIEPTS!C71 -> 0 | D71: ='OPENING STOCK'!D71 -> 0 | E71: ='OPENING STOCK'!E71+RECIEPTS!D71 -> 0 | F71: ='OPENING STOCK'!F71 -> 0 | G71: ='OPENING STOCK'!G71+RECIEPTS!E71 -> 0 | H71: ='OPENING STOCK'!H71 -> 0 | I71: ='OPENING STOCK'!I71+RECIEPTS!F71 -> 0 | J71: ='OPENING STOCK'!J71 -> 0 | K71: ='OPENING STOCK'!K71+RECIEPTS!G71 -> 0 | L71: ='OPENING STOCK'!L71 -> 0
A72: BEERS | C72: TOTAL STOCK
C73: 650 ML | E73: 500 ML TIN(CAN) | G73: 330 ML (PINT) | I73: 330 ML TIN(CAN)
A74: SL. | B74: PRODUCT NAME | C74: CASES*12 | D74: BTLS | E74: CASES*24 | F74: BTLS | G74: CASES*24 | H74: BTLS | I74: CASES*24 | J74: BTLS
A75: 1 | B75: ='SALES & RATE'!B75 -> K.F PREMIUM | C75: ='OPENING STOCK'!C75+RECIEPTS!C75 -> 1 | D75: ='OPENING STOCK'!D75 -> 15 | E75: ='OPENING STOCK'!E75+RECIEPTS!D75 -> 0 | F75: ='OPENING STOCK'!F75 -> 0 | G75: ='OPENING STOCK'!G75+RECIEPTS!E75 -> 0 | H75: ='OPENING STOCK'!H75 -> 0 | I75: ='OPENING STOCK'!I75+RECIEPTS!F75 -> 0 | J75: ='OPENING STOCK'!J75 -> 0
A76: 2 | B76: ='SALES & RATE'!B76 -> K.F STRONG | C76: ='OPENING STOCK'!C76+RECIEPTS!C76 -> 97 | D76: ='OPENING STOCK'!D76 -> 32 | E76: ='OPENING STOCK'!E76+RECIEPTS!D76 -> 2 | F76: ='OPENING STOCK'!F76 -> 1 | G76: ='OPENING STOCK'!G76+RECIEPTS!E76 -> 3 | H76: ='OPENING STOCK'!H76 -> 0 | I76: ='OPENING STOCK'!I76+RECIEPTS!F76 -> 1 | J76: ='OPENING STOCK'!J76 -> 0
A77: 3 | B77: ='SALES & RATE'!B77 -> U.B EXPORT | C77: ='OPENING STOCK'!C77+RECIEPTS!C77 -> 1 | D77: ='OPENING STOCK'!D77 -> 28 | E77: ='OPENING STOCK'!E77+RECIEPTS!D77 -> 0 | F77: ='OPENING STOCK'!F77 -> 0 | G77: ='OPENING STOCK'!G77+RECIEPTS!E77 -> 0 | H77: ='OPENING STOCK'!H77 -> 0 | I77: ='OPENING STOCK'!I77+RECIEPTS!F77 -> 0 | J77: ='OPENING STOCK'!J77 -> 0
A78: 4 | B78: ='SALES & RATE'!B78 -> KNOCK OUT | C78: ='OPENING STOCK'!C78+RECIEPTS!C78 -> 5 | D78: ='OPENING STOCK'!D78 -> 0 | E78: ='OPENING STOCK'!E78+RECIEPTS!D78 -> 0 | F78: ='OPENING STOCK'!F78 -> 0 | G78: ='OPENING STOCK'!G78+RECIEPTS!E78 -> 1 | H78: ='OPENING STOCK'!H78 -> 10 | I78: ='OPENING STOCK'!I78+RECIEPTS!F78 -> 0 | J78: ='OPENING STOCK'!J78 -> 0
A79: 5 | B79: ='SALES & RATE'!B79 -> K.F STROM | C79: ='OPENING STOCK'!C79+RECIEPTS!C79 -> 0 | D79: ='OPENING STOCK'!D79 -> 0 | E79: ='OPENING STOCK'!E79+RECIEPTS!D79 -> 0 | F79: ='OPENING STOCK'!F79 -> 0 | G79: ='OPENING STOCK'!G79+RECIEPTS!E79 -> 0 | H79: ='OPENING STOCK'!H79 -> 0 | I79: ='OPENING STOCK'!I79+RECIEPTS!F79 -> 0 | J79: ='OPENING STOCK'!J79 -> 0
...

Sheet CLOSING STOCK
A1: Mahavishnu | C1: CLOSING STOCK
C2: 750 ML | E2: 375 ML | G2: 180 ML | I2: 90 ML | K2: 60 ML
A3: SL. | B3: PRODUCT NAME | C3: CASES*12 | D3: BTLS | E3: CASES*24 | F3: BTLS | G3: CASES*48 | H3: BTLS | I3: CASES*96 | J3: BTLS | K3: BOX*25 | L3: BTLS
A4: 1 | B4: ='SALES & RATE'!B4 -> M H BRANDY | C4: ='TOTAL STOCK'!C4 -> 0 | D4: 8 | E4: 0 | F4: 24 | G4: 6 | H4: 47 | I4: 6 | J4: 73 | K4: ='TOTAL STOCK'!K4 -> 0 | L4: ='TOTAL STOCK'!L4 -> 0
A5: 2 | B5: ='SALES & RATE'!B5 -> MC BRANDY | C5: ='TOTAL STOCK'!C5 -> 0 | D5: 11 | E5: ='TOTAL STOCK'!E5 -> 1 | F5: 7 | G5: 6 | H5: 54 | I5: 5 | J5: 81 | K5: ='TOTAL STOCK'!K5 -> 0 | L5: ='TOTAL STOCK'!L5 -> 0
A6: 3 | B6: ='SALES & RATE'!B6 -> O.C.BRANDY | C6: ='TOTAL STOCK'!C6 -> 0 | D6: ='TOTAL STOCK'!D6 -> 0 | E6: ='TOTAL STOCK'!E6 -> 0 | F6: ='TOTAL STOCK'!F6 -> 0 | G6: 3 | H6: 55 | I6: 3 | J6: 64 | K6: ='TOTAL STOCK'!K6 -> 0 | L6: ='TOTAL STOCK'!L6 -> 0
A7: 4 | B7: ='SALES & RATE'!B7 -> AMRUT SILVER CUP | C7: ='TOTAL STOCK'!C7 -> 0 | D7: ='TOTAL STOCK'!D7 -> 0 | E7: ='TOTAL STOCK'!E7 -> 0 | F7: ='TOTAL STOCK'!F7 -> 0 | G7: ='TOTAL STOCK'!G7 -> 8 | H7: 26 | I7: 4 | J7: 25 | K7: ='TOTAL STOCK'!K7 -> 0 | L7: ='TOTAL STOCK'!L7 -> 0
A8: 5 | B8: ='SALES & RATE'!B8 -> HONEY BEE BRANDY | C8: ='TOTAL STOCK'!C8 -> 0 | D8: ='TOTAL STOCK'!D8 -> 0 | E8: ='TOTAL STOCK'!E8 -> 0 | F8: ='TOTAL STOCK'!F8 -> 0 | G8: ='TOTAL STOCK'!G8 -> 0 | H8: 14 | I8: ='TOTAL STOCK'!I8 -> 0 | J8: 42 | K8: ='TOTAL STOCK'!K8 -> 0 | L8: ='TOTAL STOCK'!L8 -> 0
A9: 6 | B9: ='SALES & RATE'!B9 -> O A BRANDY | C9: ='TOTAL STOCK'!C9 -> 0 | D9: ='TOTAL STOCK'!D9 -> 3 | E9: ='TOTAL STOCK'!E9 -> 0 | F9: ='TOTAL STOCK'!F9 -> 0 | G9: 1 | H9: 90 | I9: 3 | J9: 103 | K9: ='TOTAL STOCK'!K9 -> 0 | L9: ='TOTAL STOCK'!L9 -> 0
A10: 7 | B10: ='SALES & RATE'!B10 -> BEJOIS BRANDY | C10: ='TOTAL STOCK'!C10 -> 0 | D10: ='TOTAL STOCK'!D10 -> 6 | E10: ='TOTAL STOCK'!E10 -> 0 | F10: ='TOTAL STOCK'!F10 -> 0 | G10: 5 | H10: 56 | I10: 6 | J10: 21 | K10: ='TOTAL STOCK'!K10 -> 0 | L10: ='TOTAL STOCK'!L10 -> 0
A11: 8 | B11: ='SALES & RATE'!B11 -> MORPHIS BRANDY | C11: ='TOTAL STOCK'!C11 -> 0 | D11: ='TOTAL STOCK'!D11 -> 0 | E11: ='TOTAL STOCK'!E11 -> 0 | F11: ='TOTAL STOCK'!F11 -> 0 | G11: ='TOTAL STOCK'!G11 -> 0 | H11: 26 | I11: ='TOTAL STOCK'!I11 -> 0 | J11: ='TOTAL STOCK'!J11 -> 0 | K11: ='TOTAL STOCK'!K11 -> 0 | L11: 19
A12: 9 | B12: ='SALES & RATE'!B12 -> M C WHISKY | C12: ='TOTAL STOCK'!C12 -> 0 | D12: 9 | E12: ='TOTAL STOCK'!E12 -> 0 | F12: 13 | G12: 1 | H12: 22 | I12: ='TOTAL STOCK'!I12 -> 1 | J12: 41 | K12: ='TOTAL STOCK'!K12 -> 0 | L12: ='TOTAL STOCK'!L12 -> 0
A13: 10 | B13: ='SALES & RATE'!B13 -> BAGPIPER (W) | C13: ='TOTAL STOCK'!C13 -> 0 | D13: ='TOTAL STOCK'!D13 -> 11 | E13: ='TOTAL STOCK'!E13 -> 0 | F13: 7 | G13: 9 | H13: 74 | I13: 4 | J13: 15 | K13: ='TOTAL STOCK'!K13 -> 0 | L13: ='TOTAL STOCK'!L13 -> 0
A14: 11 | B14: ='SALES & RATE'!B14 -> SIGNATURE (W) | C14: ='TOTAL STOCK'!C14 -> 0 | D14: ='TOTAL STOCK'!D14 -> 0 | E14: ='TOTAL STOCK'!E14 -> 0 | F14: ='TOTAL STOCK'!F14 -> 0 | G14: ='TOTAL STOCK'!G14 -> 0 | H14: ='TOTAL STOCK'!H14 -> 31 | I14: ='TOTAL STOCK'!I14 -> 0 | J14: ='TOTAL STOCK'!J14 -> 0 | ... L14: ='TOTAL STOCK'!L14 -> 0
A15: 12 | B15: ='SALES & RATE'!B15 -> O T WHISKY | C15: ='TOTAL STOCK'!C15 -> 0 | D15: ='TOTAL STOCK'!D15 -> 0 | E15: ='TOTAL STOCK'!E15 -> 0 | F15: ='TOTAL STOCK'!F15 -> 0 | G15: ='TOTAL STOCK'!G15 -> 2 | H15: 17 | I15: ='TOTAL STOCK'!I15 -> 0 | J15: 90 | K15: ='TOTAL STOCK'!K15 -> 0 | L15: ='TOTAL STOCK'!L15 -> 0
A16: 13 | B16: ='SALES & RATE'!B16 -> DSP BLACK(W) | C16: ='TOTAL STOCK'!C16 -> 0 | D16: 7 | E16: ='TOTAL STOCK'!E16 -> 0 | F16: 0 | G16: 5 | H16: 23 | I16: 5 | J16: 101 | K16: ='TOTAL STOCK'!K16 -> 0 | L16: ='TOTAL STOCK'!L16 -> 0
A17: 14 | B17: ='SALES & RATE'!B17 -> O C WHISKY | C17: ='TOTAL STOCK'!C17 -> 0 | D17: ='TOTAL STOCK'!D17 -> 0 | E17: ='TOTAL STOCK'!E17 -> 0 | F17: ='TOTAL STOCK'!F17 -> 0 | G17: 7 | H17: 85 | I17: 3 | J17: 71 | K17: ='TOTAL STOCK'!K17 -> 0 | L17: ='TOTAL STOCK'!L17 -> 0
A18: 15 | B18: ='SALES & RATE'!B18 -> R C WHISKY | C18: ='TOTAL STOCK'!C18 -> 0 | D18: ='TOTAL STOCK'!D18 -> 0 | E18: ='TOTAL STOCK'!E18 -> 0 | F18: ='TOTAL STOCK'!F18 -> 0 | G18: ='TOTAL STOCK'!G18 -> 0 | H18: ='TOTAL STOCK'!H18 -> 0 | I18: ='TOTAL STOCK'!I18 -> 0 | J18: ='TOTAL STOCK'!J18 -> 0 | ... L18: ='TOTAL STOCK'!L18 -> 0
A19: 16 | B19: ='SALES & RATE'!B19 -> BLENDERS PRIDE | C19: ='TOTAL STOCK'!C19 -> 0 | D19: ='TOTAL STOCK'!D19 -> 0 | E19: ='TOTAL STOCK'!E19 -> 0 | F19: ='TOTAL STOCK'!F19 -> 0 | G19: ='TOTAL STOCK'!G19 -> 0 | H19: 26 | I19: ='TOTAL STOCK'!I19 -> 0 | J19: ='TOTAL STOCK'!J19 -> 0 | K19: ='TOTAL STOCK'!K19 -> 0 | L19: 4
A20: 17 | B20: ='SALES & RATE'!B20 -> AFTER DARK | C20: ='TOTAL STOCK'!C20 -> 0 | D20: ='TOTAL STOCK'!D20 -> 0 | E20: ='TOTAL STOCK'!E20 -> 0 | F20: ='TOTAL STOCK'!F20 -> 0 | G20: ='TOTAL STOCK'!G20 -> 0 | H20: ='TOTAL STOCK'!H20 -> 0 | I20: ='TOTAL STOCK'!I20 -> 0 | J20: ='TOTAL STOCK'!J20 -> 0 | ... L20: ='TOTAL STOCK'!L20 -> 0
A21: 18 | B21: ='SALES & RATE'!B21 -> B'LORE MALT (W) | C21: ='TOTAL STOCK'!C21 -> 0 | D21: ='TOTAL STOCK'!D21 -> 0 | E21: ='TOTAL STOCK'!E21 -> 0 | F21: ='TOTAL STOCK'!F21 -> 0 | G21: ='TOTAL STOCK'!G21 -> 4 | H21: 44 | I21: 4 | J21: 91 | K21: ='TOTAL STOCK'!K21 -> 0 | L21: ='TOTAL STOCK'!L21 -> 0
A22: 19 | B22: ='SALES & RATE'!B22 -> 0 | C22: ='TOTAL STOCK'!C22 -> 0 | D22: ='TOTAL STOCK'!D22 -> 0 | E22: ='TOTAL STOCK'!E22 -> 0 | F22: ='TOTAL STOCK'!F22 -> 0 | G22: ='TOTAL STOCK'!G22 -> 0 | H22: ='TOTAL STOCK'!H22 -> 0 | I22: ='TOTAL STOCK'!I22 -> 0 | J22: ='TOTAL STOCK'!J22 -> 0 | ... L22: ='TOTAL STOCK'!L22 -> 0
A23: 20 | B23: ='SALES & RATE'!B23 -> ROYAL STAGE | C23: ='TOTAL STOCK'!C23 -> 0 | D23: 4 | E23: ='TOTAL STOCK'!E23 -> 0 | F23: 7 | G23: 0 | H23: 56 | I23: ='TOTAL STOCK'!I23 -> 0 | J23: 92 | K23: ='TOTAL STOCK'!K23 -> 0 | L23: ='TOTAL STOCK'!L23 -> 0
A24: 21 | B24: ='SALES & RATE'!B24 -> HAYWARDS(W) | C24: ='TOTAL STOCK'!C24 -> 0 | D24: ='TOTAL STOCK'!D24 -> 0 | E24: ='TOTAL STOCK'!E24 -> 0 | F24: ='TOTAL STOCK'!F24 -> 0 | G24: 4 | H24: 59 | I24: 2 | J24: 68 | K24: ='TOTAL STOCK'!K24 -> 0 | L24: ='TOTAL STOCK'!L24 -> 0
A25: 22 | B25: ='SALES & RATE'!B25 -> CNB RED | C25: ='TOTAL STOCK'!C25 -> 0 | D25: ='TOTAL STOCK'!D25 -> 0 | E25: ='TOTAL STOCK'!E25 -> 0 | F25: ='TOTAL STOCK'!F25 -> 0 | G25: ='TOTAL STOCK'!G25 -> 0 | H25: 16 | I25: ='TOTAL STOCK'!I25 -> 0 | J25: ='TOTAL STOCK'!J25 -> 78 | K25: ='TOTAL STOCK'!K25 -> 0 | L25: ='TOTAL STOCK'!L25 -> 0
A26: 23 | B26: ='SALES & RATE'!B26 -> 8.PM (W) | C26: ='TOTAL STOCK'!C26 -> 0 | D26: ='TOTAL STOCK'!D26 -> 4 | E26: ='TOTAL STOCK'!E26 -> 0 | F26: ='TOTAL STOCK'!F26 -> 3 | G26: 0 | H26: 90 | I26: 0 | J26: 269 | K26: ='TOTAL STOCK'!K26 -> 0 | L26: ='TOTAL STOCK'!L26 -> 0
A27: 24 | B27: ='SALES & RATE'!B27 -> IMPERIAL BLUE(W) | C27: ='TOTAL STOCK'!C27 -> 0 | D27: 0 | E27: ='TOTAL STOCK'!E27 -> 0 | F27: 15 | G27: 5 | H27: 26 | I27: 4 | J27: 91 | K27: ='TOTAL STOCK'!K27 -> 0 | L27: ='TOTAL STOCK'!L27 -> 0
A28: 25 | B28: ='SALES & RATE'!B28 -> BLACK DOG(8)YRS | C28: ='TOTAL STOCK'!C28 -> 0 | D28: ='TOTAL STOCK'!D28 -> 0 | E28: ='TOTAL STOCK'!E28 -> 0 | F28: ='TOTAL STOCK'!F28 -> 0 | G28: ='TOTAL STOCK'!G28 -> 0 | H28: ='TOTAL STOCK'!H28 -> 13 | I28: ='TOTAL STOCK'!I28 -> 0 | J28: ='TOTAL STOCK'!J28 -> 0 | ... L28: ='TOTAL STOCK'!L28 -> 0
A29: 26 | B29: ='SALES & RATE'!B29 -> 100 PIPERS | C29: ='TOTAL STOCK'!C29 -> 0 | D29: ='TOTAL STOCK'!D29 -> 0 | E29: ='TOTAL STOCK'!E29 -> 0 | F29: ='TOTAL STOCK'!F29 -> 0 | G29: ='TOTAL STOCK'!G29 -> 0 | H29: 14 | I29: ='TOTAL STOCK'!I29 -> 0 | J29: ='TOTAL STOCK'!J29 -> 0 | K29: ='TOTAL STOCK'!K29 -> 0 | L29: 16
A30: 27 | B30: ='SALES & RATE'!B30 -> 8.PM (W) BLUE | C30: ='TOTAL STOCK'!C30 -> 0 | D30: ='TOTAL STOCK'!D30 -> 0 | E30: ='TOTAL STOCK'!E30 -> 0 | F30: ='TOTAL STOCK'!F30 -> 0 | G30: ='TOTAL STOCK'!G30 -> 0 | H30: ='TOTAL STOCK'!H30 -> 0 | I30: ='TOTAL STOCK'!I30 -> 0 | J30: ='TOTAL STOCK'!J30 -> 0 | ... L30: ='TOTAL STOCK'!L30 -> 0
A31: 28 | B31: ='SALES & RATE'!B31 -> TEACHERS HIGH | C31: ='TOTAL STOCK'!C31 -> 0 | D31: ='TOTAL STOCK'!D31 -> 0 | E31: ='TOTAL STOCK'!E31 -> 0 | F31: ='TOTAL STOCK'!F31 -> 0 | G31: ='TOTAL STOCK'!G31 -> 0 | H31: ='TOTAL STOCK'!H31 -> 0 | I31: ='TOTAL STOCK'!I31 -> 0 | J31: ='TOTAL STOCK'!J31 -> 0 | ... L31: ='TOTAL STOCK'!L31 -> 0
A32: 29 | B32: ='SALES & RATE'!B32 -> ANTIQUITY BLUE(W) | C32: ='TOTAL STOCK'!C32 -> 0 | D32: ='TOTAL STOCK'!D32 -> 0 | E32: ='TOTAL STOCK'!E32 -> 0 | F32: ='TOTAL STOCK'!F32 -> 0 | G32: ='TOTAL STOCK'!G32 -> 0 | H32: ='TOTAL STOCK'!H32 -> 0 | I32: ='TOTAL STOCK'!I32 -> 0 | J32: ='TOTAL STOCK'!J32 -> 0 | ... L32: ='TOTAL STOCK'!L32 -> 0
A33: 30 | B33: ='SALES & RATE'!B33 -> 0 | C33: ='TOTAL STOCK'!C33 -> 0 | D33: ='TOTAL STOCK'!D33 -> 0 | E33: ='TOTAL STOCK'!E33 -> 0 | F33: ='TOTAL STOCK'!F33 -> 0 | G33: ='TOTAL STOCK'!G33 -> 0 | H33: ='TOTAL STOCK'!H33 -> 0 | I33: ='TOTAL STOCK'!I33 -> 0 | J33: ='TOTAL STOCK'!J33 -> 0 | ... L33: ='TOTAL STOCK'!L33 -> 0
A34: 31 | B34: ='SALES & RATE'!B34 -> VAT 69 | C34: ='TOTAL STOCK'!C34 -> 0 | D34: ='TOTAL STOCK'!D34 -> 0 | E34: ='TOTAL STOCK'!E34 -> 0 | F34: ='TOTAL STOCK'!F34 -> 0 | G34: ='TOTAL STOCK'!G34 -> 0 | H34: ='TOTAL STOCK'!H34 -> 23 | I34: ='TOTAL STOCK'!I34 -> 0 | J34: ='TOTAL STOCK'!J34 -> 0 | ... L34: ='TOTAL STOCK'!L34 -> 0
A35: 32 | B35: ='SALES & RATE'!B35 -> HERCULES RUM | C35: ='TOTAL STOCK'!C35 -> 0 | D35: ='TOTAL STOCK'!D35 -> 5 | E35: ='TOTAL STOCK'!E35 -> 0 | F35: 19 | G35: 0 | H35: ='TOTAL STOCK'!H35 -> 54 | I35: ='TOTAL STOCK'!I35 -> 0 | J35: ='TOTAL STOCK'!J35 -> 0 | K35: ='TOTAL STOCK'!K35 -> 0 | L35: ='TOTAL STOCK'!L35 -> 0
A36: 33 | B36: ='SALES & RATE'!B36 -> M C RUM | C36: ='TOTAL STOCK'!C36 -> 0 | D36: ='TOTAL STOCK'!D36 -> 7 | E36: ='TOTAL STOCK'!E36 -> 0 | F36: ='TOTAL STOCK'!F36 -> 19 | G36: ='TOTAL STOCK'!G36 -> 0 | H36: ='TOTAL STOCK'!H36 -> 0 | I36: ='TOTAL STOCK'!I36 -> 0 | J36: ='TOTAL STOCK'!J36 -> 0 | ... L36: ='TOTAL STOCK'!L36 -> 0
A37: 34 | B37: ='SALES & RATE'!B37 -> OLD MONK RUM | C37: ='TOTAL STOCK'!C37 -> 0 | D37: 6 | E37: ='TOTAL STOCK'!E37 -> 1 | F37: 8 | G37: 8 | H37: 55 | I37: 5 | J37: 42 | K37: ='TOTAL STOCK'!K37 -> 0 | L37: ='TOTAL STOCK'!L37 -> 0
A38: 35 | B38: ='SALES & RATE'!B38 -> MC RUM CLASSIC | C38: ='TOTAL STOCK'!C38 -> 0 | D38: ='TOTAL STOCK'!D38 -> 0 | E38: ='TOTAL STOCK'!E38 -> 0 | F38: ='TOTAL STOCK'!F38 -> 0 | G38: 2 | H38: 41 | I38: 2 | J38: 115 | K38: ='TOTAL STOCK'!K38 -> 0 | L38: ='TOTAL STOCK'!L38 -> 0
A39: 36 | B39: ='SALES & RATE'!B39 -> 0 | C39: ='TOTAL STOCK'!C39 -> 0 | D39: ='TOTAL STOCK'!D39 -> 0 | E39: ='TOTAL STOCK'!E39 -> 0 | F39: ='TOTAL STOCK'!F39 -> 0 | G39: ='TOTAL STOCK'!G39 -> 0 | H39: ='TOTAL STOCK'!H39 -> 0 | I39: ='TOTAL STOCK'!I39 -> 0 | J39: ='TOTAL STOCK'!J39 -> 0 | ... L39: ='TOTAL STOCK'!L39 -> 0
A40: 37 | B40: ='SALES & RATE'!B40 -> BAGPIPER RUM | C40: ='TOTAL STOCK'!C40 -> 0 | D40: ='TOTAL STOCK'!D40 -> 0 | E40: ='TOTAL STOCK'!E40 -> 0 | F40: ='TOTAL STOCK'!F40 -> 0 | G40: 4 | H40: 67 | I40: ='TOTAL STOCK'!I40 -> 5 | J40: 33 | K40: ='TOTAL STOCK'!K40 -> 0 | L40: ='TOTAL STOCK'!L40 -> 0
...

Sheet SALES & RATE
A1: Mahavishnu | C1: SALES | M1: AMOUNT | N1: RATES
C2: 750 ML | E2: 375 ML | G2: 180 ML | I2: 90 ML | K2: 60 ML | N2: 750 ML | O2: 375 ML | P2: 180 ML | Q2: 90 ML | R2: 60 ML
A3: SL. | B3: PRODUCT NAME | C3: CASES*12 | D3: BTLS | E3: CASES*24 | F3: BTLS | G3: CASES*48 | H3: BTLS | I3: CASES*96 | J3: BTLS | K3: BOX*25 | L3: BTLS | N3: RATE | O3: RATE | P3: RATE | Q3: RATE | R3: RATE
A4: 1 | B4: M H BRANDY | C4: ='TOTAL STOCK'!C4-'CLOSING STOCK'!C4 -> 0 | D4: ='TOTAL STOCK'!D4-'CLOSING STOCK'!D4 -> 2 | E4: ='TOTAL STOCK'!E4-'CLOSING STOCK'!E4 -> 1 | F4: ='TOTAL STOCK'!F4-'CLOSING STOCK'!F4 -> -13 | G4: ='TOTAL STOCK'!G4-'CLOSING STOCK'!G4 -> 4 | H4: ='TOTAL STOCK'!H4-'CLOSING STOCK'!H4 -> -6 | I4: ='TOTAL STOCK'!I4-'CLOSING STOCK'!I4 -> 1 | J4: ='TOTAL STOCK'!J4-'CLOSING STOCK'!J4 -> -3 | ... L4: ='TOTAL STOCK'!L4-'CLOSING STOCK'!L4 -> 0 | M4: =(C4*12*N4)+(D4*N4)+(E4*24*O4)+(F4*O4)+(G4*48*P4)+(H4*P4)+(I4*96*Q4)+(J4*Q4)+(K4*25*R4)+(L4*R4) -> 73350 | N4: 1100 | O4: 550 | P4: 275 | Q4: 150 | R4: 140
A5: 2 | B5: MC BRANDY | C5: ='TOTAL STOCK'!C5-'CLOSING STOCK'!C5 -> 0 | D5: ='TOTAL STOCK'!D5-'CLOSING STOCK'!D5 -> 3 | E5: ='TOTAL STOCK'!E5-'CLOSING STOCK'!E5 -> 0 | F5: ='TOTAL STOCK'!F5-'CLOSING STOCK'!F5 -> 4 | G5: ='TOTAL STOCK'!G5-'CLOSING STOCK'!G5 -> 6 | H5: ='TOTAL STOCK'!H5-'CLOSING STOCK'!H5 -> 43 | I5: ='TOTAL STOCK'!I5-'CLOSING STOCK'!I5 -> 2 | J5: ='TOTAL STOCK'!J5-'CLOSING STOCK'!J5 -> -9 | ... L5: ='TOTAL STOCK'!L5-'CLOSING STOCK'!L5 -> 0 | M5: =(C5*12*N5)+(D5*N5)+(E5*24*O5)+(F5*O5)+(G5*48*P5)+(H5*P5)+(I5*96*Q5)+(J5*Q5)+(K5*25*R5)+(L5*R5) -> 97425 | N5: 860 | O5: 430 | P5: 215 | Q5: 120 | R5: 90
A6: 3 | B6: O.C.BRANDY | C6: ='TOTAL STOCK'!C6-'CLOSING STOCK'!C6 -> 0 | D6: ='TOTAL STOCK'!D6-'CLOSING STOCK'!D6 -> 0 | E6: ='TOTAL STOCK'!E6-'CLOSING STOCK'!E6 -> 0 | F6: ='TOTAL STOCK'!F6-'CLOSING STOCK'!F6 -> 0 | G6: ='TOTAL STOCK'!G6-'CLOSING STOCK'!G6 -> 3 | H6: ='TOTAL STOCK'!H6-'CLOSING STOCK'!H6 -> 34 | I6: ='TOTAL STOCK'!I6-'CLOSING STOCK'!I6 -> 2 | J6: ='TOTAL STOCK'!J6-'CLOSING STOCK'!J6 -> -22 | ... L6: ='TOTAL STOCK'!L6-'CLOSING STOCK'!L6 -> 0 | M6: =(C6*12*N6)+(D6*N6)+(E6*24*O6)+(F6*O6)+(G6*48*P6)+(H6*P6)+(I6*96*Q6)+(J6*Q6)+(K6*25*R6)+(L6*R6) -> 28930 | N6: 400 | O6: 200 | P6: 110 | Q6: 55
A7: 4 | B7: AMRUT SILVER CUP | C7: ='TOTAL STOCK'!C7-'CLOSING STOCK'!C7 -> 0 | D7: ='TOTAL STOCK'!D7-'CLOSING STOCK'!D7 -> 0 | E7: ='TOTAL STOCK'!E7-'CLOSING STOCK'!E7 -> 0 | F7: ='TOTAL STOCK'!F7-'CLOSING STOCK'!F7 -> 0 | G7: ='TOTAL STOCK'!G7-'CLOSING STOCK'!G7 -> 0 | H7: ='TOTAL STOCK'!H7-'CLOSING STOCK'!H7 -> 20 | I7: ='TOTAL STOCK'!I7-'CLOSING STOCK'!I7 -> 2 | J7: ='TOTAL STOCK'!J7-'CLOSING STOCK'!J7 -> -23 | ... L7: ='TOTAL STOCK'!L7-'CLOSING STOCK'!L7 -> 0 | M7: =(C7*12*N7)+(D7*N7)+(E7*24*O7)+(F7*O7)+(G7*48*P7)+(H7*P7)+(I7*96*Q7)+(J7*Q7)+(K7*25*R7)+(L7*R7) -> 10650 | N7: 400 | O7: 200 | P7: 110 | Q7: 50
A8: 5 | B8: HONEY BEE BRANDY | C8: ='TOTAL STOCK'!C8-'CLOSING STOCK'!C8 -> 0 | D8: ='TOTAL STOCK'!D8-'CLOSING STOCK'!D8 -> 0 | E8: ='TOTAL STOCK'!E8-'CLOSING STOCK'!E8 -> 0 | F8: ='TOTAL STOCK'!F8-'CLOSING STOCK'!F8 -> 0 | G8: ='TOTAL STOCK'!G8-'CLOSING STOCK'!G8 -> 0 | H8: ='TOTAL STOCK'!H8-'CLOSING STOCK'!H8 -> 12 | I8: ='TOTAL STOCK'!I8-'CLOSING STOCK'!I8 -> 0 | J8: ='TOTAL STOCK'!J8-'CLOSING STOCK'!J8 -> 12 | ... L8: ='TOTAL STOCK'!L8-'CLOSING STOCK'!L8 -> 0 | M8: =(C8*12*N8)+(D8*N8)+(E8*24*O8)+(F8*O8)+(G8*48*P8)+(H8*P8)+(I8*96*Q8)+(J8*Q8)+(K8*25*R8)+(L8*R8) -> 3240 | N8: 720 | O8: 360 | P8: 180 | Q8: 90
A9: 6 | B9: O A BRANDY | C9: ='TOTAL STOCK'!C9-'CLOSING STOCK'!C9 -> 0 | D9: ='TOTAL STOCK'!D9-'CLOSING STOCK'!D9 -> 0 | E9: ='TOTAL STOCK'!E9-'CLOSING STOCK'!E9 -> 0 | F9: ='TOTAL STOCK'!F9-'CLOSING STOCK'!F9 -> 0 | G9: ='TOTAL STOCK'!G9-'CLOSING STOCK'!G9 -> 2 | H9: ='TOTAL STOCK'!H9-'CLOSING STOCK'!H9 -> 2 | I9: ='TOTAL STOCK'!I9-'CLOSING STOCK'!I9 -> 1 | J9: ='TOTAL STOCK'!J9-'CLOSING STOCK'!J9 -> -42 | ... L9: ='TOTAL STOCK'!L9-'CLOSING STOCK'!L9 -> 0 | M9: =(C9*9*N9)+(D9*N9)+(E9*24*O9)+(F9*O9)+(G9*48*P9)+(H9*P9)+(I9*96*Q9)+(J9*Q9)+(K9*25*R9)+(L9*R9) -> 19780 | N9: 700 | O9: 350 | P9: 155 | Q9: 85
A10: 7 | B10: BEJOIS BRANDY | C10: ='TOTAL STOCK'!C10-'CLOSING STOCK'!C10 -> 0 | D10: ='TOTAL STOCK'!D10-'CLOSING STOCK'!D10 -> 0 | E10: ='TOTAL STOCK'!E10-'CLOSING STOCK'!E10 -> 0 | F10: ='TOTAL STOCK'!F10-'CLOSING STOCK'!F10 -> 0 | G10: ='TOTAL STOCK'!G10-'CLOSING STOCK'!G10 -> 3 | H10: ='TOTAL STOCK'!H10-'CLOSING STOCK'!H10 -> 3 | I10: ='TOTAL STOCK'!I10-'CLOSING STOCK'!I10 -> 1 | J10: ='TOTAL STOCK'!J10-'CLOSING STOCK'!J10 -> -2 | ... L10: ='TOTAL STOCK'!L10-'CLOSING STOCK'!L10 -> 0 | M10: =(C10*9*N10)+(D10*N10)+(E10*24*O10)+(F10*O10)+(G10*48*P10)+(H10*P10)+(I10*96*Q10)+(J10*Q10)+(K10*25*R10)+(L10*R10) -> 30775 | N10: 700 | O10: 350 | P10: 155 | Q10: 85
A11: 8 | B11: MORPHIS BRANDY | C11: ='TOTAL STOCK'!C11-'CLOSING STOCK'!C11 -> 0 | D11: ='TOTAL STOCK'!D11-'CLOSING STOCK'!D11 -> 0 | E11: ='TOTAL STOCK'!E11-'CLOSING STOCK'!E11 -> 0 | F11: ='TOTAL STOCK'!F11-'CLOSING STOCK'!F11 -> 0 | G11: ='TOTAL STOCK'!G11-'CLOSING STOCK'!G11 -> 0 | H11: ='TOTAL STOCK'!H11-'CLOSING STOCK'!H11 -> 9 | I11: ='TOTAL STOCK'!I11-'CLOSING STOCK'!I11 -> 0 | J11: ='TOTAL STOCK'!J11-'CLOSING STOCK'!J11 -> 0 | ... L11: ='TOTAL STOCK'!L11-'CLOSING STOCK'!L11 -> 14 | M11: =(C11*12*N11)+(D11*N11)+(E11*24*O11)+(F11*O11)+(G11*48*P11)+(H11*P11)+(I11*96*Q11)+(J11*Q11)+(K11*25*R11)+(L11*R11) -> 6290 | N11: 1800 | O11: 900 | P11: 450 | Q11: 225 | R11: 160
A12: 9 | B12: M C WHISKY | C12: ='TOTAL STOCK'!C12-'CLOSING STOCK'!C12 -> 0 | D12: ='TOTAL STOCK'!D12-'CLOSING STOCK'!D12 -> 1 | E12: ='TOTAL STOCK'!E12-'CLOSING STOCK'!E12 -> 0 | F12: ='TOTAL STOCK'!F12-'CLOSING STOCK'!F12 -> 2 | G12: ='TOTAL STOCK'!G12-'CLOSING STOCK'!G12 -> 1 | H12: ='TOTAL STOCK'!H12-'CLOSING STOCK'!H12 -> 30 | I12: ='TOTAL STOCK'!I12-'CLOSING STOCK'!I12 -> 0 | J12: ='TOTAL STOCK'!J12-'CLOSING STOCK'!J12 -> 54 | ... L12: ='TOTAL STOCK'!L12-'CLOSING STOCK'!L12 -> 0 | M12: =(C12*12*N12)+(D12*N12)+(E12*24*O12)+(F12*O12)+(G12*48*P12)+(H12*P12)+(I12*96*Q12)+(J12*Q12)+(K12*25*R12)+(L12*R12) -> 31210 | N12: 1100 | O12: 550 | P12: 275 | Q12: 140
A13: 10 | B13: BAGPIPER (W) | C13: ='TOTAL STOCK'!C13-'CLOSING STOCK'!C13 -> 0 | D13: ='TOTAL STOCK'!D13-'CLOSING STOCK'!D13 -> 0 | E13: ='TOTAL STOCK'!E13-'CLOSING STOCK'!E13 -> 0 | F13: ='TOTAL STOCK'!F13-'CLOSING STOCK'!F13 -> 2 | G13: ='TOTAL STOCK'!G13-'CLOSING STOCK'!G13 -> 7 | H13: ='TOTAL STOCK'!H13-'CLOSING STOCK'!H13 -> -23 | I13: ='TOTAL STOCK'!I13-'CLOSING STOCK'!I13 -> 2 | J13: ='TOTAL STOCK'!J13-'CLOSING STOCK'!J13 -> 34 | ... L13: ='TOTAL STOCK'!L13-'CLOSING STOCK'!L13 -> 0 | M13: =(C13*12*N13)+(D13*N13)+(E13*24*O13)+(F13*O13)+(G13*48*P13)+(H13*P13)+(I13*96*Q13)+(J13*Q13)+(K13*25*R13)+(L13*R13) -> 68425 | N13: 700 | O13: 350 | P13: 155 | Q13: 85
A14: 11 | B14: SIGNATURE (W) | C14: ='TOTAL STOCK'!C14-'CLOSING STOCK'!C14 -> 0 | D14: ='TOTAL STOCK'!D14-'CLOSING STOCK'!D14 -> 0 | E14: ='TOTAL STOCK'!E14-'CLOSING STOCK'!E14 -> 0 | F14: ='TOTAL STOCK'!F14-'CLOSING STOCK'!F14 -> 0 | G14: ='TOTAL STOCK'!G14-'CLOSING STOCK'!G14 -> 0 | H14: ='TOTAL STOCK'!H14-'CLOSING STOCK'!H14 -> 0 | I14: ='TOTAL STOCK'!I14-'CLOSING STOCK'!I14 -> 0 | J14: ='TOTAL STOCK'!J14-'CLOSING STOCK'!J14 -> 0 | ... L14: ='TOTAL STOCK'!L14-'CLOSING STOCK'!L14 -> 0 | M14: =(C14*12*N14)+(D14*N14)+(E14*24*O14)+(F14*O14)+(G14*48*P14)+(H14*P14)+(I14*96*Q14)+(J14*Q14)+(K14*25*R14)+(L14*R14) -> 0 | N14: 2000 | O14: 1000 | P14: 500 | Q14: 250 | R14: 200
A15: 12 | B15: O T WHISKY | C15: ='TOTAL STOCK'!C15-'CLOSING STOCK'!C15 -> 0 | D15: ='TOTAL STOCK'!D15-'CLOSING STOCK'!D15 -> 0 | E15: ='TOTAL STOCK'!E15-'CLOSING STOCK'!E15 -> 0 | F15: ='TOTAL STOCK'!F15-'CLOSING STOCK'!F15 -> 0 | G15: ='TOTAL STOCK'!G15-'CLOSING STOCK'!G15 -> 0 | H15: ='TOTAL STOCK'!H15-'CLOSING STOCK'!H15 -> 6 | I15: ='TOTAL STOCK'!I15-'CLOSING STOCK'!I15 -> 0 | J15: ='TOTAL STOCK'!J15-'CLOSING STOCK'!J15 -> 9 | ... L15: ='TOTAL STOCK'!L15-'CLOSING STOCK'!L15 -> 0 | M15: =(C15*12*N15)+(D15*N15)+(E15*24*O15)+(F15*O15)+(G15*48*P15)+(H15*P15)+(I15*96*Q15)+(J15*Q15)+(K15*25*R15)+(L15*R15) -> 1695 | N15: 520 | O15: 260 | P15: 155 | Q15: 85
A16: 13 | B16: DSP BLACK(W) | C16: ='TOTAL STOCK'!C16-'CLOSING STOCK'!C16 -> 0 | D16: ='TOTAL STOCK'!D16-'CLOSING STOCK'!D16 -> 1 | E16: ='TOTAL STOCK'!E16-'CLOSING STOCK'!E16 -> 0 | F16: ='TOTAL STOCK'!F16-'CLOSING STOCK'!F16 -> 4 | G16: ='TOTAL STOCK'!G16-'CLOSING STOCK'!G16 -> 2 | H16: ='TOTAL STOCK'!H16-'CLOSING STOCK'!H16 -> 31 | I16: ='TOTAL STOCK'!I16-'CLOSING STOCK'!I16 -> 1 | J16: ='TOTAL STOCK'!J16-'CLOSING STOCK'!J16 -> -36 | ... L16: ='TOTAL STOCK'!L16-'CLOSING STOCK'!L16 -> 0 | M16: =(C16*12*N16)+(D16*N16)+(E16*24*O16)+(F16*O16)+(G16*48*P16)+(H16*P16)+(I16*96*Q16)+(J16*Q16)+(K16*25*R16)+(L16*R16) -> 37085 | N16: 860 | O16: 430 | P16: 215 | Q16: 120
A17: 14 | B17: O C WHISKY | C17: ='TOTAL STOCK'!C17-'CLOSING STOCK'!C17 -> 0 | D17: ='TOTAL STOCK'!D17-'CLOSING STOCK'!D17 -> 0 | E17: ='TOTAL STOCK'!E17-'CLOSING STOCK'!E17 -> 0 | F17: ='TOTAL STOCK'!F17-'CLOSING STOCK'!F17 -> 0 | G17: ='TOTAL STOCK'!G17-'CLOSING STOCK'!G17 -> 4 | H17: ='TOTAL STOCK'!H17-'CLOSING STOCK'!H17 -> -12 | I17: ='TOTAL STOCK'!I17-'CLOSING STOCK'!I17 -> 2 | J17: ='TOTAL STOCK'!J17-'CLOSING STOCK'!J17 -> 14 | ... L17: ='TOTAL STOCK'!L17-'CLOSING STOCK'!L17 -> 0 | M17: =(C17*12*N17)+(D17*N17)+(E17*24*O17)+(F17*O17)+(G17*48*P17)+(H17*P17)+(I17*96*Q17)+(J17*Q17)+(K17*25*R17)+(L17*R17) -> 31130 | N17: 400 | O17: 200 | P17: 110 | Q17: 55
A18: 15 | B18: R C WHISKY | C18: ='TOTAL STOCK'!C18-'CLOSING STOCK'!C18 -> 0 | D18: ='TOTAL STOCK'!D18-'CLOSING STOCK'!D18 -> 0 | E18: ='TOTAL STOCK'!E18-'CLOSING STOCK'!E18 -> 0 | F18: ='TOTAL STOCK'!F18-'CLOSING STOCK'!F18 -> 0 | G18: ='TOTAL STOCK'!G18-'CLOSING STOCK'!G18 -> 0 | H18: ='TOTAL STOCK'!H18-'CLOSING STOCK'!H18 -> 0 | I18: ='TOTAL STOCK'!I18-'CLOSING STOCK'!I18 -> 0 | J18: ='TOTAL STOCK'!J18-'CLOSING STOCK'!J18 -> 0 | ... L18: ='TOTAL STOCK'!L18-'CLOSING STOCK'!L18 -> 0 | M18: =(C18*12*N18)+(D18*N18)+(E18*24*O18)+(F18*O18)+(G18*48*P18)+(H18*P18)+(I18*96*Q18)+(J18*Q18)+(K18*25*R18)+(L18*R18) -> 0 | N18: 1800 | O18: 900 | P18: 340 | Q18: 195
A19: 16 | B19: BLENDERS PRIDE | C19: ='TOTAL STOCK'!C19-'CLOSING STOCK'!C19 -> 0 | D19: ='TOTAL STOCK'!D19-'CLOSING STOCK'!D19 -> 0 | E19: ='TOTAL STOCK'!E19-'CLOSING STOCK'!E19 -> 0 | F19: ='TOTAL STOCK'!F19-'CLOSING STOCK'!F19 -> 0 | G19: ='TOTAL STOCK'!G19-'CLOSING STOCK'!G19 -> 0 | H19: ='TOTAL STOCK'!H19-'CLOSING STOCK'!H19 -> 4 | I19: ='TOTAL STOCK'!I19-'CLOSING STOCK'!I19 -> 0 | J19: ='TOTAL STOCK'!J19-'CLOSING STOCK'!J19 -> 0 | ... L19: ='TOTAL STOCK'!L19-'CLOSING STOCK'!L19 -> 11 | M19: =(C19*12*N19)+(D19*N19)+(E19*24*O19)+(F19*O19)+(G19*48*P19)+(H19*P19)+(I19*96*Q19)+(J19*Q19)+(K19*25*R19)+(L19*R19) -> 3910 | N19: 2000 | O19: 1000 | P19: 510 | Q19: 240 | R19: 170
A20: 17 | B20: AFTER DARK | C20: ='TOTAL STOCK'!C20-'CLOSING STOCK'!C20 -> 0 | D20: ='TOTAL STOCK'!D20-'CLOSING STOCK'!D20 -> 0 | E20: ='TOTAL STOCK'!E20-'CLOSING STOCK'!E20 -> 0 | F20: ='TOTAL STOCK'!F20-'CLOSING STOCK'!F20 -> 0 | G20: ='TOTAL STOCK'!G20-'CLOSING STOCK'!G20 -> 0 | H20: ='TOTAL STOCK'!H20-'CLOSING STOCK'!H20 -> 0 | I20: ='TOTAL STOCK'!I20-'CLOSING STOCK'!I20 -> 0 | J20: ='TOTAL STOCK'!J20-'CLOSING STOCK'!J20 -> 0 | ... L20: ='TOTAL STOCK'!L20-'CLOSING STOCK'!L20 -> 0 | M20: =(C20*12*N20)+(D20*N20)+(E20*24*O20)+(F20*O20)+(G20*48*P20)+(H20*P20)+(I20*96*Q20)+(J20*Q20)+(K20*25*R20)+(L20*R20) -> 0 | N20: 1080 | O20: 540 | P20: 270 | Q20: 150
A21: 18 | B21: B'LORE MALT (W) | C21: ='TOTAL STOCK'!C21-'CLOSING STOCK'!C21 -> 0 | D21: ='TOTAL STOCK'!D21-'CLOSING STOCK'!D21 -> 0 | E21: ='TOTAL STOCK'!E21-'CLOSING STOCK'!E21 -> 0 | F21: ='TOTAL STOCK'!F21-'CLOSING STOCK'!F21 -> 0 | G21: ='TOTAL STOCK'!G21-'CLOSING STOCK'!G21 -> 0 | H21: ='TOTAL STOCK'!H21-'CLOSING STOCK'!H21 -> 2 | I21: ='TOTAL STOCK'!I21-'CLOSING STOCK'!I21 -> 1 | J21: ='TOTAL STOCK'!J21-'CLOSING STOCK'!J21 -> -71 | ... L21: ='TOTAL STOCK'!L21-'CLOSING STOCK'!L21 -> 0 | M21: =(C21*12*N21)+(D21*N21)+(E21*24*O21)+(F21*O21)+(G21*48*P21)+(H21*P21)+(I21*96*Q21)+(J21*Q21)+(K21*25*R21)+(L21*R21) -> 1450 | N21: 340 | O21: 170 | P21: 100 | Q21: 50
A22: 19 | B22: 0 | C22: ='TOTAL STOCK'!C22-'CLOSING STOCK'!C22 -> 0 | D22: ='TOTAL STOCK'!D22-'CLOSING STOCK'!D22 -> 0 | E22: ='TOTAL STOCK'!E22-'CLOSING STOCK'!E22 -> 0 | F22: ='TOTAL STOCK'!F22-'CLOSING STOCK'!F22 -> 0 | G22: ='TOTAL STOCK'!G22-'CLOSING STOCK'!G22 -> 0 | H22: ='TOTAL STOCK'!H22-'CLOSING STOCK'!H22 -> 0 | I22: ='TOTAL STOCK'!I22-'CLOSING STOCK'!I22 -> 0 | J22: ='TOTAL STOCK'!J22-'CLOSING STOCK'!J22 -> 0 | ... L22: ='TOTAL STOCK'!L22-'CLOSING STOCK'!L22 -> 0 | M22: =(C22*12*N22)+(D22*N22)+(E22*24*O22)+(F22*O22)+(G22*48*P22)+(H22*P22)+(I22*96*Q22)+(J22*Q22)+(K22*25*R22)+(L22*R22) -> 0 | N22: 480 | O22: 240 | P22: 120 | Q22: 75
A23: 20 | B23: ROYAL STAGE | C23: ='TOTAL STOCK'!C23-'CLOSING STOCK'!C23 -> 0 | D23: ='TOTAL STOCK'!D23-'CLOSING STOCK'!D23 -> 1 | E23: ='TOTAL STOCK'!E23-'CLOSING STOCK'!E23 -> 0 | F23: ='TOTAL STOCK'!F23-'CLOSING STOCK'!F23 -> 4 | G23: ='TOTAL STOCK'!G23-'CLOSING STOCK'!G23 -> 1 | H23: ='TOTAL STOCK'!H23-'CLOSING STOCK'!H23 -> -34 | I23: ='TOTAL STOCK'!I23-'CLOSING STOCK'!I23 -> 0 | J23: ='TOTAL STOCK'!J23-'CLOSING STOCK'!J23 -> -2 | ... L23: ='TOTAL STOCK'!L23-'CLOSING STOCK'!L23 -> 0 | M23: =(C23*12*N23)+(D23*N23)+(E23*24*O23)+(F23*O23)+(G23*48*P23)+(H23*P23)+(I23*96*Q23)+(J23*Q23)+(K23*25*R23)+(L23*R23) -> 8740 | N23: 1400 | O23: 700 | P23: 350 | Q23: 180 | R23: 120
A24: 21 | B24: HAYWARDS(W) | C24: ='TOTAL STOCK'!C24-'CLOSING STOCK'!C24 -> 0 | D24: ='TOTAL STOCK'!D24-'CLOSING STOCK'!D24 -> 0 | E24: ='TOTAL STOCK'!E24-'CLOSING STOCK'!E24 -> 0 | F24: ='TOTAL STOCK'!F24-'CLOSING STOCK'!F24 -> 0 | G24: ='TOTAL STOCK'!G24-'CLOSING STOCK'!G24 -> 1 | H24: ='TOTAL STOCK'!H24-'CLOSING STOCK'!H24 -> -26 | I24: ='TOTAL STOCK'!I24-'CLOSING STOCK'!I24 -> 1 | J24: ='TOTAL STOCK'!J24-'CLOSING STOCK'!J24 -> -20 | ... L24: ='TOTAL STOCK'!L24-'CLOSING STOCK'!L24 -> 0 | M24: =(C24*12*N24)+(D24*N24)+(E24*24*O24)+(F24*O24)+(G24*48*P24)+(H24*P24)+(I24*96*Q24)+(J24*Q24)+(K24*25*R24)+(L24*R24) -> 7200 | N24: 400 | O24: 200 | P24: 120 | Q24: 60
A25: 22 | B25: CNB RED | C25: ='TOTAL STOCK'!C25-'CLOSING STOCK'!C25 -> 0 | D25: ='TOTAL STOCK'!D25-'CLOSING STOCK'!D25 -> 0 | E25: ='TOTAL STOCK'!E25-'CLOSING STOCK'!E25 -> 0 | F25: ='TOTAL STOCK'!F25-'CLOSING STOCK'!F25 -> 0 | G25: ='TOTAL STOCK'!G25-'CLOSING STOCK'!G25 -> 0 | H25: ='TOTAL STOCK'!H25-'CLOSING STOCK'!H25 -> 1 | I25: ='TOTAL STOCK'!I25-'CLOSING STOCK'!I25 -> 0 | J25: ='TOTAL STOCK'!J25-'CLOSING STOCK'!J25 -> 0 | ... L25: ='TOTAL STOCK'!L25-'CLOSING STOCK'!L25 -> 0 | M25: =(C25*12*N25)+(D25*N25)+(E25*24*O25)+(F25*O25)+(G25*48*P25)+(H25*P25)+(I25*96*Q25)+(J25*Q25)+(K25*25*R25)+(L25*R25) -> 220 | N25: 880 | O25: 440 | P25: 220 | Q25: 120
A26: 23 | B26: 8.PM (W) | C26: ='TOTAL STOCK'!C26-'CLOSING STOCK'!C26 -> 0 | D26: ='TOTAL STOCK'!D26-'CLOSING STOCK'!D26 -> 0 | E26: ='TOTAL STOCK'!E26-'CLOSING STOCK'!E26 -> 0 | F26: ='TOTAL STOCK'!F26-'CLOSING STOCK'!F26 -> 0 | G26: ='TOTAL STOCK'!G26-'CLOSING STOCK'!G26 -> 1 | H26: ='TOTAL STOCK'!H26-'CLOSING STOCK'!H26 -> -17 | I26: ='TOTAL STOCK'!I26-'CLOSING STOCK'!I26 -> 1 | J26: ='TOTAL STOCK'!J26-'CLOSING STOCK'!J26 -> -73 | ... L26: ='TOTAL STOCK'!L26-'CLOSING STOCK'!L26 -> 0 | M26: =(C26*12*N26)+(D26*N26)+(E26*24*O26)+(F26*O26)+(G26*48*P26)+(H26*P26)+(I26*96*Q26)+(J26*Q26)+(K26*25*R26)+(L26*R26) -> 6760 | N26: 600 | O26: 300 | P26: 155 | Q26: 85
A27: 24 | B27: IMPERIAL BLUE(W) | C27: ='TOTAL STOCK'!C27-'CLOSING STOCK'!C27 -> 0 | D27: ='TOTAL STOCK'!D27-'CLOSING STOCK'!D27 -> 2 | E27: ='TOTAL STOCK'!E27-'CLOSING STOCK'!E27 -> 0 | F27: ='TOTAL STOCK'!F27-'CLOSING STOCK'!F27 -> 9 | G27: ='TOTAL STOCK'!G27-'CLOSING STOCK'!G27 -> 2 | H27: ='TOTAL STOCK'!H27-'CLOSING STOCK'!H27 -> 3 | I27: ='TOTAL STOCK'!I27-'CLOSING STOCK'!I27 -> 1 | J27: ='TOTAL STOCK'!J27-'CLOSING STOCK'!J27 -> -34 | ... L27: ='TOTAL STOCK'!L27-'CLOSING STOCK'!L27 -> 0 | M27: =(C27*12*N27)+(D27*N27)+(E27*24*O27)+(F27*O27)+(G27*48*P27)+(H27*P27)+(I27*96*Q27)+(J27*Q27)+(K27*25*R27)+(L27*R27) -> 43675 | N27: 1100 | O27: 550 | P27: 275 | Q27: 150
A28: 25 | B28: BLACK DOG(8)YRS | C28: ='TOTAL STOCK'!C28-'CLOSING STOCK'!C28 -> 0 | D28: ='TOTAL STOCK'!D28-'CLOSING STOCK'!D28 -> 0 | E28: ='TOTAL STOCK'!E28-'CLOSING STOCK'!E28 -> 0 | F28: ='TOTAL STOCK'!F28-'CLOSING STOCK'!F28 -> 0 | G28: ='TOTAL STOCK'!G28-'CLOSING STOCK'!G28 -> 0 | H28: ='TOTAL STOCK'!H28-'CLOSING STOCK'!H28 -> 0 | I28: ='TOTAL STOCK'!I28-'CLOSING STOCK'!I28 -> 0 | J28: ='TOTAL STOCK'!J28-'CLOSING STOCK'!J28 -> 0 | ... L28: ='TOTAL STOCK'!L28-'CLOSING STOCK'!L28 -> 0 | M28: =(C28*12*N28)+(D28*N28)+(E28*24*O28)+(F28*O28)+(G28*48*P28)+(H28*P28)+(I28*96*Q28)+(J28*Q28)+(K28*25*R28)+(L28*R28) -> 0 | N28: 2720 | O28: 1360 | P28: 680 | Q28: 340 | R28: 250
A29: 26 | B29: 100 PIPERS | C29: ='TOTAL STOCK'!C29-'CLOSING STOCK'!C29 -> 0 | D29: ='TOTAL STOCK'!D29-'CLOSING STOCK'!D29 -> 0 | E29: ='TOTAL STOCK'!E29-'CLOSING STOCK'!E29 -> 0 | F29: ='TOTAL STOCK'!F29-'CLOSING STOCK'!F29 -> 0 | G29: ='TOTAL STOCK'!G29-'CLOSING STOCK'!G29 -> 0 | H29: ='TOTAL STOCK'!H29-'CLOSING STOCK'!H29 -> 1 | I29: ='TOTAL STOCK'!I29-'CLOSING STOCK'!I29 -> 0 | J29: ='TOTAL STOCK'!J29-'CLOSING STOCK'!J29 -> 0 | ... L29: ='TOTAL STOCK'!L29-'CLOSING STOCK'!L29 -> 6 | M29: =(C29*12*N29)+(D29*N29)+(E29*24*O29)+(F29*O29)+(G29*48*P29)+(H29*P29)+(I29*96*Q29)+(J29*Q29)+(K29*25*R29)+(L29*R29) -> 2180 | N29: 2720 | O29: 1360 | P29: 680 | Q29: 340 | R29: 250
A30: 27 | B30: 8.PM (W) BLUE | C30: ='TOTAL STOCK'!C30-'CLOSING STOCK'!C30 -> 0 | D30: ='TOTAL STOCK'!D30-'CLOSING STOCK'!D30 -> 0 | E30: ='TOTAL STOCK'!E30-'CLOSING STOCK'!E30 -> 0 | F30: ='TOTAL STOCK'!F30-'CLOSING STOCK'!F30 -> 0 | G30: ='TOTAL STOCK'!G30-'CLOSING STOCK'!G30 -> 0 | H30: ='TOTAL STOCK'!H30-'CLOSING STOCK'!H30 -> 0 | I30: ='TOTAL STOCK'!I30-'CLOSING STOCK'!I30 -> 0 | J30: ='TOTAL STOCK'!J30-'CLOSING STOCK'!J30 -> 0 | ... L30: ='TOTAL STOCK'!L30-'CLOSING STOCK'!L30 -> 0 | M30: =(C30*12*N30)+(D30*N30)+(E30*24*O30)+(F30*O30)+(G30*48*P30)+(H30*P30)+(I30*96*Q30)+(J30*Q30)+(K30*25*R30)+(L30*R30) -> 0 | N30: 720 | O30: 360 | P30: 180 | Q30: 90
A31: 28 | B31: TEACHERS HIGH | C31: ='TOTAL STOCK'!C31-'CLOSING STOCK'!C31 -> 0 | D31: ='TOTAL STOCK'!D31-'CLOSING STOCK'!D31 -> 0 | E31: ='TOTAL STOCK'!E31-'CLOSING STOCK'!E31 -> 0 | F31: ='TOTAL STOCK'!F31-'CLOSING STOCK'!F31 -> 0 | G31: ='TOTAL STOCK'!G31-'CLOSING STOCK'!G31 -> 0 | H31: ='TOTAL STOCK'!H31-'CLOSING STOCK'!H31 -> 0 | I31: ='TOTAL STOCK'!I31-'CLOSING STOCK'!I31 -> 0 | J31: ='TOTAL STOCK'!J31-'CLOSING STOCK'!J31 -> 0 | ... L31: ='TOTAL STOCK'!L31-'CLOSING STOCK'!L31 -> 0 | M31: =(C31*12*N31)+(D31*N31)+(E31*24*O31)+(F31*O31)+(G31*48*P31)+(H31*P31)+(I31*96*Q31)+(J31*Q31)+(K31*25*R31)+(L31*R31) -> 0 | N31: 2600 | O31: 1300 | P31: 750 | R31: 250
A32: 29 | B32: ANTIQUITY BLUE(W) | C32: ='TOTAL STOCK'!C32-'CLOSING STOCK'!C32 -> 0 | D32: ='TOTAL STOCK'!D32-'CLOSING STOCK'!D32 -> 0 | E32: ='TOTAL STOCK'!E32-'CLOSING STOCK'!E32 -> 0 | F32: ='TOTAL STOCK'!F32-'CLOSING STOCK'!F32 -> 0 | G32: ='TOTAL STOCK'!G32-'CLOSING STOCK'!G32 -> 0 | H32: ='TOTAL STOCK'!H32-'CLOSING STOCK'!H32 -> 0 | I32: ='TOTAL STOCK'!I32-'CLOSING STOCK'!I32 -> 0 | J32: ='TOTAL STOCK'!J32-'CLOSING STOCK'!J32 -> 0 | ... L32: ='TOTAL STOCK'!L32-'CLOSING STOCK'!L32 -> 0 | M32: =(C32*12*N32)+(D32*N32)+(E32*24*O32)+(F32*O32)+(G32*48*P32)+(H32*P32)+(I32*96*Q32)+(J32*Q32)+(K32*25*R32)+(L32*R32) -> 0 | N32: 1920 | O32: 960 | P32: 480 | Q32: 240 | R32: 170
A33: 30 | B33: 0 | C33: ='TOTAL STOCK'!C33-'CLOSING STOCK'!C33 -> 0 | D33: ='TOTAL STOCK'!D33-'CLOSING STOCK'!D33 -> 0 | E33: ='TOTAL STOCK'!E33-'CLOSING STOCK'!E33 -> 0 | F33: ='TOTAL STOCK'!F33-'CLOSING STOCK'!F33 -> 0 | G33: ='TOTAL STOCK'!G33-'CLOSING STOCK'!G33 -> 0 | H33: ='TOTAL STOCK'!H33-'CLOSING STOCK'!H33 -> 0 | I33: ='TOTAL STOCK'!I33-'CLOSING STOCK'!I33 -> 0 | J33: ='TOTAL STOCK'!J33-'CLOSING STOCK'!J33 -> 0 | ... L33: ='TOTAL STOCK'!L33-'CLOSING STOCK'!L33 -> 0 | M33: =(C33*12*N33)+(D33*N33)+(E33*24*O33)+(F33*O33)+(G33*48*P33)+(H33*P33)+(I33*96*Q33)+(J33*Q33)+(K33*25*R33)+(L33*R33) -> 0
A34: 31 | B34: VAT 69 | C34: ='TOTAL STOCK'!C34-'CLOSING STOCK'!C34 -> 0 | D34: ='TOTAL STOCK'!D34-'CLOSING STOCK'!D34 -> 0 | E34: ='TOTAL STOCK'!E34-'CLOSING STOCK'!E34 -> 0 | F34: ='TOTAL STOCK'!F34-'CLOSING STOCK'!F34 -> 0 | G34: ='TOTAL STOCK'!G34-'CLOSING STOCK'!G34 -> 0 | H34: ='TOTAL STOCK'!H34-'CLOSING STOCK'!H34 -> 0 | I34: ='TOTAL STOCK'!I34-'CLOSING STOCK'!I34 -> 0 | J34: ='TOTAL STOCK'!J34-'CLOSING STOCK'!J34 -> 0 | ... L34: ='TOTAL STOCK'!L34-'CLOSING STOCK'!L34 -> 0 | M34: =(C34*12*N34)+(D34*N34)+(E34*24*O34)+(F34*O34)+(G34*48*P34)+(H34*P34)+(I34*96*Q34)+(J34*Q34)+(K34*25*R34)+(L34*R34) -> 0 | N34: 2700 | O34: 1350 | P34: 670 | Q34: 340 | R34: 240
A35: 32 | B35: HERCULES RUM | C35: ='TOTAL STOCK'!C35-'CLOSING STOCK'!C35 -> 0 | D35: ='TOTAL STOCK'!D35-'CLOSING STOCK'!D35 -> 0 | E35: ='TOTAL STOCK'!E35-'CLOSING STOCK'!E35 -> 0 | F35: ='TOTAL STOCK'!F35-'CLOSING STOCK'!F35 -> 2 | G35: ='TOTAL STOCK'!G35-'CLOSING STOCK'!G35 -> 1 | H35: ='TOTAL STOCK'!H35-'CLOSING STOCK'!H35 -> 0 | I35: ='TOTAL STOCK'!I35-'CLOSING STOCK'!I35 -> 0 | J35: ='TOTAL STOCK'!J35-'CLOSING STOCK'!J35 -> 0 | ... L35: ='TOTAL STOCK'!L35-'CLOSING STOCK'!L35 -> 0 | M35: =(C35*12*N35)+(D35*N35)+(E35*24*O35)+(F35*O35)+(G35*48*P35)+(H35*P35)+(I35*96*Q35)+(J35*Q35)+(K35*25*R35)+(L35*R35) -> 14560 | N35: 1120 | O35: 560 | P35: 280 | Q35: 140
A36: 33 | B36: M C RUM | C36: ='TOTAL STOCK'!C36-'CLOSING STOCK'!C36 -> 0 | D36: ='TOTAL STOCK'!D36-'CLOSING STOCK'!D36 -> 0 | E36: ='TOTAL STOCK'!E36-'CLOSING STOCK'!E36 -> 0 | F36: ='TOTAL STOCK'!F36-'CLOSING STOCK'!F36 -> 0 | G36: ='TOTAL STOCK'!G36-'CLOSING STOCK'!G36 -> 0 | H36: ='TOTAL STOCK'!H36-'CLOSING STOCK'!H36 -> 0 | I36: ='TOTAL STOCK'!I36-'CLOSING STOCK'!I36 -> 0 | J36: ='TOTAL STOCK'!J36-'CLOSING STOCK'!J36 -> 0 | ... L36: ='TOTAL STOCK'!L36-'CLOSING STOCK'!L36 -> 0 | M36: =(C36*12*N36)+(D36*N36)+(E36*24*O36)+(F36*O36)+(G36*48*P36)+(H36*P36)+(I36*96*Q36)+(J36*Q36)+(K36*25*R36)+(L36*R36) -> 0 | N36: 880 | O36: 440 | P36: 170 | Q36: 90
A37: 34 | B37: OLD MONK RUM | C37: ='TOTAL STOCK'!C37-'CLOSING STOCK'!C37 -> 0 | D37: ='TOTAL STOCK'!D37-'CLOSING STOCK'!D37 -> 1 | E37: ='TOTAL STOCK'!E37-'CLOSING STOCK'!E37 -> 0 | F37: ='TOTAL STOCK'!F37-'CLOSING STOCK'!F37 -> 1 | G37: ='TOTAL STOCK'!G37-'CLOSING STOCK'!G37 -> 3 | H37: ='TOTAL STOCK'!H37-'CLOSING STOCK'!H37 -> 29 | I37: ='TOTAL STOCK'!I37-'CLOSING STOCK'!I37 -> 1 | J37: ='TOTAL STOCK'!J37-'CLOSING STOCK'!J37 -> 8 | ... L37: ='TOTAL STOCK'!L37-'CLOSING STOCK'!L37 -> 0 | M37: =(C37*12*N37)+(D37*N37)+(E37*24*O37)+(F37*O37)+(G37*48*P37)+(H37*P37)+(I37*96*Q37)+(J37*Q37)+(K37*25*R37)+(L37*R37) -> 40955 | N37: 880 | O37: 440 | P37: 175 | Q37: 90
A38: 35 | B38: MC RUM CLASSIC | C38: ='TOTAL STOCK'!C38-'CLOSING STOCK'!C38 -> 0 | D38: ='TOTAL STOCK'!D38-'CLOSING STOCK'!D38 -> 0 | E38: ='TOTAL STOCK'!E38-'CLOSING STOCK'!E38 -> 0 | F38: ='TOTAL STOCK'!F38-'CLOSING STOCK'!F38 -> 0 | G38: ='TOTAL STOCK'!G38-'CLOSING STOCK'!G38 -> 1 | H38: ='TOTAL STOCK'!H38-'CLOSING STOCK'!H38 -> 8 | I38: ='TOTAL STOCK'!I38-'CLOSING STOCK'!I38 -> 1 | J38: ='TOTAL STOCK'!J38-'CLOSING STOCK'!J38 -> -42 | ... L38: ='TOTAL STOCK'!L38-'CLOSING STOCK'!L38 -> 0 | M38: =(C38*12*N38)+(D38*N38)+(E38*24*O38)+(F38*O38)+(G38*48*P38)+(H38*P38)+(I38*96*Q38)+(J38*Q38)+(K38*25*R38)+(L38*R38) -> 13270 | N38: 600 | O38: 300 | P38: 155 | Q38: 85
A39: 36 | B39: 0 | C39: ='TOTAL STOCK'!C39-'CLOSING STOCK'!C39 -> 0 | D39: ='TOTAL STOCK'!D39-'CLOSING STOCK'!D39 -> 0 | E39: ='TOTAL STOCK'!E39-'CLOSING STOCK'!E39 -> 0 | F39: ='TOTAL STOCK'!F39-'CLOSING STOCK'!F39 -> 0 | G39: ='TOTAL STOCK'!G39-'CLOSING STOCK'!G39 -> 0 | H39: ='TOTAL STOCK'!H39-'CLOSING STOCK'!H39 -> 0 | I39: ='TOTAL STOCK'!I39-'CLOSING STOCK'!I39 -> 0 | J39: ='TOTAL STOCK'!J39-'CLOSING STOCK'!J39 -> 0 | ... L39: ='TOTAL STOCK'!L39-'CLOSING STOCK'!L39 -> 0 | M39: =(C39*12*N39)+(D39*N39)+(E39*24*O39)+(F39*O39)+(G39*48*P39)+(H39*P39)+(I39*96*Q39)+(J39*Q39)+(K39*25*R39)+(L39*R39) -> 0
A40: 37 | B40: BAGPIPER RUM | C40: ='TOTAL STOCK'!C40-'CLOSING STOCK'!C40 -> 0 | D40: ='TOTAL STOCK'!D40-'CLOSING STOCK'!D40 -> 0 | E40: ='TOTAL STOCK'!E40-'CLOSING STOCK'!E40 -> 0 | F40: ='TOTAL STOCK'!F40-'CLOSING STOCK'!F40 -> 0 | G40: ='TOTAL STOCK'!G40-'CLOSING STOCK'!G40 -> 1 | H40: ='TOTAL STOCK'!H40-'CLOSING STOCK'!H40 -> 10 | I40: ='TOTAL STOCK'!I40-'CLOSING STOCK'!I40 -> 0 | J40: ='TOTAL STOCK'!J40-'CLOSING STOCK'!J40 -> 26 | ... L40: ='TOTAL STOCK'!L40-'CLOSING STOCK'!L40 -> 0 | M40: =(C40*12*N40)+(D40*N40)+(E40*24*O40)+(F40*O40)+(G40*48*P40)+(H40*P40)+(I40*96*Q40)+(J40*Q40)+(K40*25*R40)+(L40*R40) -> 9360 | N40: 400 | O40: 200 | P40: 130 | Q40: 70
...

Sheet EXPENDITURE
A1: DATE | B1: PARTICULARS | C1: AMOUNT
C2: 147440
B10: TOTAL | C10: =SUM(C2:C9) -> 147440
